<?xml version="1.0" ?>
<!-- =================================================================================== -->
<!-- |    This document was autogenerated by xacro from /home/alex/additive_manufacturing/Planner4grasping/src/fingrip_ign_moveit2/fingrip_description/urdf/fingrip.urdf.xacro | -->
<!-- |    EDITING THIS FILE BY HAND IS NOT RECOMMENDED                                 | -->
<!-- =================================================================================== -->
<!-- URDF for Franka Emika fingrip -->
<robot name="fingrip">
  <!--            -->
  <!-- Properties -->
  <!--            -->
  <!--            -->
  <!-- Properties -->
  <!--            -->
  <!--            -->
  <!-- Properties -->
  <!--            -->
  <!--            -->
  <!-- Properties -->
  <!--            -->
  <!-- Import Rviz colors -->
  <material name="Grey">
    <color rgba="0.2 0.2 0.2 1.0"/>
  </material>
  <material name="Orange">
    <color rgba="1.0 0.423529411765 0.0392156862745 1.0"/>
  </material>
  <material name="Blue">
    <color rgba="0.5 0.7 1.0 1.0"/>
  </material>
  <link name="world">
  </link>
  <joint name="fingrip_joint_base" type="fixed">
    <parent link="world"/>
    <child link="fingrip_link0"/>
    <origin rpy="0 0 0" xyz="0 0 0"/>
  </joint>
  <link name="fingrip_link0">
    <visual>
      <origin rpy="0 0 0" xyz="0 0 0"/>
      <geometry>
        <mesh filename="package://fingrip_description/meshes/visual/arm/link0.stl"/>
      </geometry>
      <material name="Grey"/>
    </visual>
    <collision>
      <origin rpy="0 0 0" xyz="0 0 0"/>
      <geometry>
        <mesh filename="package://fingrip_description/meshes/collision/arm/link0.stl"/>
      </geometry>
    </collision>
    <inertial>
      <origin rpy="0 0 0" xyz="-0.1 0 0.07"/>
      <mass value="2.814271300104062"/>
      <inertia ixx="0.0075390636364814695" ixy="-1.5053124574783335e-05" ixz="-0.0012144328835738973" iyy="0.010508017427382959" iyz="1.0434803501032979e-05" izz="0.009864933638708275"/>
    </inertial>
  </link>
  <gazebo reference="fingrip_link0">
    <mu1 value="0.85"/>
    <mu2 value="0.85"/>
  </gazebo>
  <joint name="fingrip_joint1" type="revolute">
    <parent link="fingrip_link0"/>
    <child link="fingrip_link1"/>
    <origin rpy="0 0 0" xyz="0 0 0.1575"/>
    <axis xyz="0 0 1"/>
    <limit effort="87" lower="-2.9670597283903604" upper="2.9670597283903604" velocity="1.4835298641951802"/>
    <dynamics damping="21.75" friction="3.48"/>
  </joint>
  <transmission name="fingrip_joint1_transmission">
    <type>transmission_interface/SimpleTransmission</type>
    <joint name="fingrip_joint1">
      <hardwareInterface>hardware_interface/EffortJointInterface</hardwareInterface>
    </joint>
    <actuator name="fingrip_joint1_actuator">
      <mechanicalReduction>1</mechanicalReduction>
    </actuator>
  </transmission>
  <gazebo reference="fingrip_joint1">
    <springStiffness value="0.0"/>
    <springReference value="0.0"/>
  </gazebo>
  <link name="fingrip_link1">
    <visual>
      <origin rpy="0 0 0" xyz="0 0 0"/>
      <geometry>
        <mesh filename="package://fingrip_description/meshes/visual/arm/link1.stl"/>
      </geometry>
      <material name="Blue"/>
    </visual>
    <collision>
      <origin rpy="0 0 0" xyz="0 0 0"/>
      <geometry>
        <mesh filename="package://fingrip_description/meshes/collision/arm/link1.stl"/>
      </geometry>
    </collision>
    <inertial>
      <origin rpy="0 0 0" xyz="0 -0.03 0.12"/>
      <mass value="2.6433170427227215"/>
      <inertia ixx="0.017405076982879724" ixy="-8.687986369621078e-09" ixz="-1.6277819062920423e-08" iyy="0.015352077935781732" iyz="0.004510855959102245" izz="0.005987891663073857"/>
    </inertial>
  </link>
  <gazebo reference="fingrip_link1">
    <mu1 value="0.85"/>
    <mu2 value="0.85"/>
  </gazebo>
  <joint name="fingrip_joint2" type="revolute">
    <parent link="fingrip_link1"/>
    <child link="fingrip_link2"/>
    <origin rpy="1.5707963267948966 0 -3.141592653589793" xyz="0 0 0.2025"/>
    <axis xyz="0 0 1"/>
    <limit effort="87" lower="-2.0943951023931953" upper="2.0943951023931953" velocity="1.4835298641951802"/>
    <dynamics damping="21.75" friction="3.48"/>
  </joint>
  <transmission name="fingrip_joint2_transmission">
    <type>transmission_interface/SimpleTransmission</type>
    <joint name="fingrip_joint2">
      <hardwareInterface>hardware_interface/EffortJointInterface</hardwareInterface>
    </joint>
    <actuator name="fingrip_joint2_actuator">
      <mechanicalReduction>1</mechanicalReduction>
    </actuator>
  </transmission>
  <gazebo reference="fingrip_joint2">
    <springStiffness value="0.0"/>
    <springReference value="0.0"/>
  </gazebo>
  <link name="fingrip_link2">
    <visual>
      <origin rpy="0 0 0" xyz="0 0 0"/>
      <geometry>
        <mesh filename="package://fingrip_description/meshes/visual/arm/link2.stl"/>
      </geometry>
      <material name="Blue"/>
    </visual>
    <collision>
      <origin rpy="0 0 0" xyz="0 0 0"/>
      <geometry>
        <mesh filename="package://fingrip_description/meshes/collision/arm/link2.stl"/>
      </geometry>
    </collision>
    <inertial>
      <origin rpy="0 0 0" xyz="0.00029 0.059   0.042"/>
      <mass value="2.6652755331661186"/>
      <inertia ixx="0.01778694005635383" ixy="8.70635625879119e-08" ixz="3.752072058394008e-08" iyy="0.006044133867952844" iyz="-0.004599490295490376" izz="0.01571095500455695"/>
    </inertial>
  </link>
  <gazebo reference="fingrip_link2">
    <mu1 value="0.85"/>
    <mu2 value="0.85"/>
  </gazebo>
  <joint name="fingrip_joint3" type="revolute">
    <parent link="fingrip_link2"/>
    <child link="fingrip_link3"/>
    <origin rpy="1.5707963267948966 0 -3.141592653589793" xyz="0 0.2045 0"/>
    <axis xyz="0 0 1"/>
    <limit effort="87" lower="-2.9670597283903604" upper="2.9670597283903604" velocity="1.7453292519943295"/>
    <dynamics damping="21.75" friction="3.48"/>
  </joint>
  <transmission name="fingrip_joint3_transmission">
    <type>transmission_interface/SimpleTransmission</type>
    <joint name="fingrip_joint3">
      <hardwareInterface>hardware_interface/EffortJointInterface</hardwareInterface>
    </joint>
    <actuator name="fingrip_joint3_actuator">
      <mechanicalReduction>1</mechanicalReduction>
    </actuator>
  </transmission>
  <gazebo reference="fingrip_joint3">
    <springStiffness value="0.0"/>
    <springReference value="0.0"/>
  </gazebo>
  <link name="fingrip_link3">
    <visual>
      <origin rpy="0 0 0" xyz="0 0 0"/>
      <geometry>
        <mesh filename="package://fingrip_description/meshes/visual/arm/link3.stl"/>
      </geometry>
      <material name="Orange"/>
    </visual>
    <collision>
      <origin rpy="0 0 0" xyz="0 0 0"/>
      <geometry>
        <mesh filename="package://fingrip_description/meshes/collision/arm/link3.stl"/>
      </geometry>
    </collision>
    <inertial>
      <origin rpy="0 0 0" xyz="0   0.03 0.13"/>
      <mass value="2.3293714829045733"/>
      <inertia ixx="0.0075496764161139766" ixy="-0.0024320464513492225" ixz="-0.003250815048103007" iyy="0.009680676080191398" iyz="-0.0021316282421730694" izz="0.007944557422008086"/>
    </inertial>
  </link>
  <gazebo reference="fingrip_link3">
    <mu1 value="0.85"/>
    <mu2 value="0.85"/>
  </gazebo>
  <joint name="fingrip_joint4" type="revolute">
    <parent link="fingrip_link3"/>
    <child link="fingrip_link4"/>
    <origin rpy="1.5707963267948966 0 0" xyz="0.0 0.0 0.2155"/>
    <axis xyz="0 0 1"/>
    <limit effort="87" lower="-2.0943951023931953" upper="2.0943951023931953" velocity="1.3089969389957472"/>
    <dynamics damping="21.75" friction="3.48"/>
  </joint>
  <transmission name="fingrip_joint4_transmission">
    <type>transmission_interface/SimpleTransmission</type>
    <joint name="fingrip_joint4">
      <hardwareInterface>hardware_interface/EffortJointInterface</hardwareInterface>
    </joint>
    <actuator name="fingrip_joint4_actuator">
      <mechanicalReduction>1</mechanicalReduction>
    </actuator>
  </transmission>
  <gazebo reference="fingrip_joint4">
    <springStiffness value="0.0"/>
    <springReference value="0.0"/>
  </gazebo>
  <link name="fingrip_link4">
    <visual>
      <origin rpy="0 0 0" xyz="0 0 0"/>
      <geometry>
        <mesh filename="package://fingrip_description/meshes/visual/arm/link4.stl"/>
      </geometry>
      <material name="Blue"/>
    </visual>
    <collision>
      <origin rpy="0 0 0" xyz="0 0 0"/>
      <geometry>
        <mesh filename="package://fingrip_description/meshes/collision/arm/link4.stl"/>
      </geometry>
    </collision>
    <inertial>
      <origin rpy="0 0 0" xyz="0 0.067 0.034"/>
      <mass value="2.3104763646281508"/>
      <inertia ixx="0.007764568814864828" ixy="0.003371475204045935" ixz="-0.002343621113168248" iyy="0.008015776929980149" iyz="0.0022917526161470624" izz="0.009955882308071066"/>
    </inertial>
  </link>
  <gazebo reference="fingrip_link4">
    <mu1 value="0.85"/>
    <mu2 value="0.85"/>
  </gazebo>
  <joint name="fingrip_joint5" type="revolute">
    <parent link="fingrip_link4"/>
    <child link="fingrip_link5"/>
    <origin rpy="1.5707963267948966 0 3.141592653589793" xyz="0.0 0.1845 0.0"/>
    <axis xyz="0 0 1"/>
    <limit effort="12" lower="-2.9670597283903604" upper="2.9670597283903604" velocity="2.2689280275926285"/>
    <dynamics damping="3.0" friction="0.48"/>
  </joint>
  <transmission name="fingrip_joint5_transmission">
    <type>transmission_interface/SimpleTransmission</type>
    <joint name="fingrip_joint5">
      <hardwareInterface>hardware_interface/EffortJointInterface</hardwareInterface>
    </joint>
    <actuator name="fingrip_joint5_actuator">
      <mechanicalReduction>1</mechanicalReduction>
    </actuator>
  </transmission>
  <gazebo reference="fingrip_joint5">
    <springStiffness value="0.0"/>
    <springReference value="0.0"/>
  </gazebo>
  <link name="fingrip_link5">
    <visual>
      <origin rpy="0 0 0" xyz="0 0 0"/>
      <geometry>
        <mesh filename="package://fingrip_description/meshes/visual/arm/link5.stl"/>
      </geometry>
      <material name="Blue"/>
    </visual>
    <collision>
      <origin rpy="0 0 0" xyz="0 0 0"/>
      <geometry>
        <mesh filename="package://fingrip_description/meshes/collision/arm/link5.stl"/>
      </geometry>
    </collision>
    <inertial>
      <origin rpy="0 0 0" xyz="0.0001 0.021  0.076"/>
      <mass value="2.6226426154892004"/>
      <inertia ixx="0.029070538014399377" ixy="6.208738268725568e-07" ixz="-1.0059151925023392e-05" iyy="0.027638529986528795" iyz="-0.007424306477850814" izz="0.004251111234400737"/>
    </inertial>
  </link>
  <gazebo reference="fingrip_link5">
    <mu1 value="0.85"/>
    <mu2 value="0.85"/>
  </gazebo>
  <joint name="fingrip_joint6" type="revolute">
    <parent link="fingrip_link5"/>
    <child link="fingrip_link6"/>
    <origin rpy="1.5707963267948966 0 0" xyz="0.0 0.0 0.2155"/>
    <axis xyz="0 0 1"/>
    <limit effort="12" lower="-2.0943951023931953" upper="2.0943951023931953" velocity="2.356194490192345"/>
    <dynamics damping="3.0" friction="0.48"/>
  </joint>
  <transmission name="fingrip_joint6_transmission">
    <type>transmission_interface/SimpleTransmission</type>
    <joint name="fingrip_joint6">
      <hardwareInterface>hardware_interface/EffortJointInterface</hardwareInterface>
    </joint>
    <actuator name="fingrip_joint6_actuator">
      <mechanicalReduction>1</mechanicalReduction>
    </actuator>
  </transmission>
  <gazebo reference="fingrip_joint6">
    <springStiffness value="0.0"/>
    <springReference value="0.0"/>
  </gazebo>
  <link name="fingrip_link6">
    <visual>
      <origin rpy="0 0 0" xyz="0 0 0"/>
      <geometry>
        <mesh filename="package://fingrip_description/meshes/visual/arm/link6.stl"/>
      </geometry>
      <material name="Orange"/>
    </visual>
    <collision>
      <origin rpy="0 0 0" xyz="0 0 0"/>
      <geometry>
        <mesh filename="package://fingrip_description/meshes/collision/arm/link6.stl"/>
      </geometry>
    </collision>
    <inertial>
      <origin rpy="0 0 0" xyz="0.0 0.00059 0.0004"/>
      <mass value="1.5025804886626795"/>
      <inertia ixx="0.002940555801469018" ixy="-0.00042391108351381507" ixz="0.000610007735338717" iyy="0.00392105201248677" iyz="0.00012647545430836214" izz="0.0054115603870960195"/>
    </inertial>
  </link>
  <gazebo reference="fingrip_link6">
    <mu1 value="0.85"/>
    <mu2 value="0.85"/>
  </gazebo>
  <joint name="fingrip_joint7" type="revolute">
    <parent link="fingrip_link6"/>
    <child link="fingrip_link7"/>
    <origin rpy="1.5707963267948966 0 -3.141592653589793" xyz="0.0 0.081 0.0"/>
    <axis xyz="0 0 1"/>
    <limit effort="12" lower="-3.0543261909900763" upper="3.0543261909900763" velocity="2.356194490192345"/>
    <dynamics damping="3.0" friction="0.48"/>
  </joint>
  <transmission name="fingrip_joint7_transmission">
    <type>transmission_interface/SimpleTransmission</type>
    <joint name="fingrip_joint7">
      <hardwareInterface>hardware_interface/EffortJointInterface</hardwareInterface>
    </joint>
    <actuator name="fingrip_joint7_actuator">
      <mechanicalReduction>1</mechanicalReduction>
    </actuator>
  </transmission>
  <gazebo reference="fingrip_joint7">
    <springStiffness value="0.0"/>
    <springReference value="0.0"/>
  </gazebo>
  <link name="fingrip_link7">
    <visual>
      <origin rpy="0 0 0" xyz="0 0 0"/>
      <geometry>
        <mesh filename="package://fingrip_description/meshes/visual/arm/link7.stl"/>
      </geometry>
      <material name="Grey"/>
    </visual>
    <collision>
      <origin rpy="0 0 0" xyz="0 0 0"/>
      <geometry>
        <mesh filename="package://fingrip_description/meshes/collision/arm/link7.stl"/>
      </geometry>
    </collision>
    <inertial>
      <origin rpy="0 0 0" xyz="0.0 0.0 0.02"/>
      <mass value="0.5237668134788256"/>
      <inertia ixx="0.0008621467959726535" ixy="-0.00011871071570425467" ixz="3.866602604509339e-05" iyy="0.0008613100184801048" iyz="-9.057841649422724e-05" izz="0.0006961139396618219"/>
    </inertial>
  </link>
  <gazebo reference="fingrip_link7">
    <mu1 value="0.85"/>
    <mu2 value="0.85"/>
  </gazebo>
  <link name="fingrip_link8">
  </link>
  <joint name="fingrip_link8_virtual_joint" type="fixed">
    <parent link="fingrip_link7"/>
    <child link="fingrip_link8"/>
    <origin rpy="0 0 0" xyz="0 0 0.132936"/>
  </joint>
  <ros2_control name="fingrip_arm_system" type="system">
    <hardware>
      <plugin>gz_ros2_control/GazeboSimSystem</plugin>
    </hardware>
    <joint name="fingrip_joint1">
      <command_interface name="effort"/>
      <state_interface name="position">
        <param name="initial_position">1.884</param>
      </state_interface>
      <state_interface name="velocity"/>
      <state_interface name="effort"/>
    </joint>
    <joint name="fingrip_joint2">
      <param name="initial_position">-0.6105</param>
      <command_interface name="effort"/>
      <state_interface name="position">
        <param name="initial_position">-0.6105</param>
      </state_interface>
      <state_interface name="velocity"/>
      <state_interface name="effort"/>
    </joint>
    <joint name="fingrip_joint3">
      <param name="initial_position">2.7038</param>
      <command_interface name="effort"/>
      <state_interface name="position"/>
      <state_interface name="velocity"/>
      <state_interface name="effort"/>
    </joint>
    <joint name="fingrip_joint4">
      <param name="initial_position">1.535</param>
      <command_interface name="effort"/>
      <state_interface name="position"/>
      <state_interface name="velocity"/>
      <state_interface name="effort"/>
    </joint>
    <joint name="fingrip_joint5">
      <param name="initial_position">-1.256</param>
      <command_interface name="effort"/>
      <state_interface name="position"/>
      <state_interface name="velocity"/>
      <state_interface name="effort"/>
    </joint>
    <joint name="fingrip_joint6">
      <param name="initial_position">-1.744</param>
      <command_interface name="effort"/>
      <state_interface name="position"/>
      <state_interface name="velocity"/>
      <state_interface name="effort"/>
    </joint>
    <joint name="fingrip_joint7">
      <param name="initial_position">-2.1816</param>
      <command_interface name="effort"/>
      <state_interface name="position"/>
      <state_interface name="velocity"/>
      <state_interface name="effort"/>
    </joint>
  </ros2_control>
  <joint name="fingrip_joint_wrist" type="fixed">
    <parent link="fingrip_link8"/>
    <child link="fingrip_hand"/>
    <origin rpy="0 0 0" xyz="0 0 0.0"/>
  </joint>
  <link name="fingrip_hand">
    <visual>
      <origin rpy="0 0 0" xyz="0 0 0"/>
      <geometry>
        <mesh filename="package://fingrip_description/meshes/visual/gripper/paume/base_hand_paume1.stl"/>
      </geometry>
      <material name="Grey"/>
    </visual>
    <collision>
      <origin rpy="0 0 0" xyz="0 0 0"/>
      <geometry>
        <mesh filename="package://fingrip_description/meshes/collision/gripper/paume/base_hand_paume1.stl"/>
      </geometry>
    </collision>
    <inertial>
      <origin rpy="0 0 0" xyz="0.00 0.0 -0.04835"/>
      <mass value="0.14060765127978503"/>
      <inertia ixx="0.0005365450414352072" ixy="1.7911952957732454e-08" ixz="-2.320071910601251e-08" iyy="7.70511954783727e-05" iyz="4.681149945315967e-08" izz="0.0004938176882694914"/>
    </inertial>
  </link>
  <gazebo reference="fingrip_hand">
    <mu1 value="0.85"/>
    <mu2 value="0.85"/>
  </gazebo>
  <joint name="fingrip_joint_palm" type="fixed">
    <parent link="fingrip_hand"/>
    <child link="fingrip_palm"/>
    <origin rpy="0 0 0" xyz="0 0 0.013"/>
  </joint>
  <link name="fingrip_palm">
    <visual>
      <origin rpy="0 0 0" xyz="0 0 0"/>
      <geometry>
        <mesh filename="package://fingrip_description/meshes/visual/gripper/case/case_3d.stl"/>
      </geometry>
      <material name="Grey"/>
    </visual>
    <collision>
      <origin rpy="0 0 0" xyz="0 0 0"/>
      <geometry>
        <mesh filename="package://fingrip_description/meshes/collision/gripper/case/case_3d.stl"/>
      </geometry>
    </collision>
    <inertial>
      <origin rpy="0 0 0" xyz="0 0 0.0"/>
      <mass value="0.14060765127978503"/>
      <inertia ixx="0.0005365450414352072" ixy="1.7911952957732454e-08" ixz="-2.320071910601251e-08" iyy="7.70511954783727e-05" iyz="4.681149945315967e-08" izz="0.0004938176882694914"/>
    </inertial>
  </link>
  <gazebo reference="fingrip_palm">
    <mu1 value="0.85"/>
    <mu2 value="0.85"/>
  </gazebo>
  <joint name="fingrip_finger1_base_joint" type="revolute">
    <parent link="fingrip_hand"/>
    <child link="fingrip_finger1_base_link"/>
    <origin rpy="0 -1.5707963267948966 -3.141592653589793" xyz="0.054 0.054 0.09885097"/>
    <axis xyz="1 0 0"/>
    <limit effort="20" lower="-1.5707963267948966" upper="0" velocity="1.57"/>
    <dynamics damping="3.0" friction="0.4"/>
  </joint>
  <transmission name="fingrip_finger1_base_joint_transmission">
    <type>transmission_interface/SimpleTransmission</type>
    <joint name="fingrip_finger1_base_joint">
      <hardwareInterface>hardware_interface/EffortJointInterface</hardwareInterface>
    </joint>
    <actuator name="fingrip_finger1_base_joint_actuator">
      <mechanicalReduction>1</mechanicalReduction>
    </actuator>
  </transmission>
  <gazebo reference="fingrip_finger1_base_joint">
    <springStiffness value="0.0"/>
    <springReference value="0.0"/>
  </gazebo>
  <link name="fingrip_finger1_base_link">
    <visual>
      <origin rpy="0 0 0" xyz="0 0 0"/>
      <geometry>
        <mesh filename="package://fingrip_description/meshes/visual/gripper/base_finger/base_finger.stl"/>
      </geometry>
      <material name="Grey"/>
    </visual>
    <collision>
      <origin rpy="0 0 0" xyz="0 0 0"/>
      <geometry>
        <mesh filename="package://fingrip_description/meshes/collision/gripper/base_finger/base_finger.stl"/>
      </geometry>
    </collision>
    <inertial>
      <origin rpy="0 0 0" xyz="-0.0465 -0.04775 -0.0"/>
      <mass value="0.2238453537819424"/>
      <inertia ixx="0.0007" ixy="-0.0002" ixz="0.0" iyy="0.0006" iyz="0.0" izz="0.0011"/>
    </inertial>
  </link>
  <gazebo reference="fingrip_finger1_base_link">
    <mu1 value="1.13"/>
    <mu2 value="1.13"/>
  </gazebo>
  <joint name="fingrip_finger1_proximal_joint" type="revolute">
    <parent link="fingrip_finger1_base_link"/>
    <child link="fingrip_finger1_proximal_link"/>
    <origin rpy="0 0 0" xyz="0 -0.03255 0"/>
    <axis xyz="0 0 1"/>
    <limit effort="20" lower="-1.3" upper="0.31416" velocity="1.57"/>
    <dynamics damping="3.0" friction="0.4"/>
  </joint>
  <transmission name="fingrip_finger1_proximal_joint_transmission">
    <type>transmission_interface/SimpleTransmission</type>
    <joint name="fingrip_finger1_proximal_joint">
      <hardwareInterface>hardware_interface/EffortJointInterface</hardwareInterface>
    </joint>
    <actuator name="fingrip_finger1_proximal_joint_actuator">
      <mechanicalReduction>1</mechanicalReduction>
    </actuator>
  </transmission>
  <gazebo reference="fingrip_finger1_proximal_joint">
    <springStiffness value="0.0"/>
    <springReference value="0.0"/>
  </gazebo>
  <link name="fingrip_finger1_proximal_link">
    <visual>
      <origin rpy="0 0 0" xyz="0 0 0"/>
      <geometry>
        <mesh filename="package://fingrip_description/meshes/visual/gripper/proximal/short/proximal.stl"/>
      </geometry>
      <material name="Grey"/>
    </visual>
    <collision>
      <origin rpy="0 0 0" xyz="0 0 0"/>
      <geometry>
        <mesh filename="package://fingrip_description/meshes/collision/gripper/proximal/short/proximal.stl"/>
      </geometry>
    </collision>
    <inertial>
      <origin rpy="0 0 0" xyz="0.03411 -0.01012 0.0"/>
      <mass value="0.150"/>
      <inertia ixx="0.000092" ixy="-0.000061" ixz="0.0" iyy="0.00031" iyz="0.0" izz="0.00031"/>
    </inertial>
  </link>
  <gazebo reference="fingrip_finger1_proximal_link">
    <mu1 value="1.13"/>
    <mu2 value="1.13"/>
  </gazebo>
  <joint name="fingrip_finger1_intermediaire_joint" type="revolute">
    <parent link="fingrip_finger1_proximal_link"/>
    <child link="fingrip_finger1_intermediaire_link"/>
    <origin rpy="0 0 0" xyz="0.08 0 0"/>
    <axis xyz="0 0 1"/>
    <limit effort="20" lower="-0.5" upper="1.0472" velocity="1.57"/>
    <dynamics damping="3.0" friction="0.4"/>
  </joint>
  <transmission name="fingrip_finger1_intermediaire_joint_transmission">
    <type>transmission_interface/SimpleTransmission</type>
    <joint name="fingrip_finger1_intermediaire_joint">
      <hardwareInterface>hardware_interface/EffortJointInterface</hardwareInterface>
    </joint>
    <actuator name="fingrip_finger1_intermediaire_joint_actuator">
      <mechanicalReduction>1</mechanicalReduction>
    </actuator>
  </transmission>
  <gazebo reference="fingrip_finger1_intermediaire_joint">
    <springStiffness value="0.0"/>
    <springReference value="0.0"/>
  </gazebo>
  <link name="fingrip_finger1_intermediaire_link">
    <visual>
      <origin rpy="0 0 0" xyz="0 0 0"/>
      <geometry>
        <mesh filename="package://fingrip_description/meshes/visual/gripper/intermediaire/short/intermediaire.stl"/>
      </geometry>
      <material name="Grey"/>
    </visual>
    <collision>
      <origin rpy="0 0 0" xyz="0 0 0"/>
      <geometry>
        <mesh filename="package://fingrip_description/meshes/collision/gripper/intermediaire/short/intermediaire.stl"/>
      </geometry>
    </collision>
    <inertial>
      <origin rpy="0 0 0" xyz="0.01791 -0.01023 0.0"/>
      <mass value="0.150"/>
      <inertia ixx="0.000025" ixy="0.000013" ixz="0.0" iyy="0.000102" iyz="0.0" izz="0.000108"/>
    </inertial>
  </link>
  <gazebo reference="fingrip_finger1_intermediaire_link">
    <mu1 value="1.13"/>
    <mu2 value="1.13"/>
  </gazebo>
  <!-- DISTAL limb -->
  <!--
        <xacro:fingrip_joint
        parent="${prefix}${finger_name}${intermediaire_prefix}${link_prefix}"
        child="${prefix}${finger_name}${distal_prefix}${link_prefix}"
        joint_name="${prefix}${finger_name}${distal_prefix}${joint_prefix}"
        joint_type="${joint_other_type}"
        joint_origin_xyz="${joint_other_origin_xyz}"
        joint_origin_rpy="${joint_other_origin_rpy}"
        joint_axis_xyz="${joint_other_axis_xyz}"
        joint_lower_limit="${joint_lower_limit}"
        joint_upper_limit="${joint_upper_limit}"
        joint_velocity_limit="${joint_velocity_limit}"
        joint_torque_limit="${joint_torque_limit}"
        joint_damping="${joint_damping}"
        joint_friction="${joint_friction}"
        gazebo_preserve_fixed_joint="${gazebo_preserve_fixed_joint}"
        />

        <xacro:fingrip_link
        link_name="${prefix}${finger_name}${distal_prefix}${link_prefix}"
        mesh="${distal_mesh_path}${short_prefix}${distal_mesh_name}"
        collision="${collision}"
        mu="${link_mu}"
        />
        -->
  <joint name="fingrip_finger2_base_joint" type="revolute">
    <parent link="fingrip_hand"/>
    <child link="fingrip_finger2_base_link"/>
    <origin rpy="3.141592653589793 -1.5707963267948966 3.141592653589793" xyz="0.054 -0.054 0.09885097"/>
    <axis xyz="1 0 0"/>
    <limit effort="20" lower="0" upper="1.5707963267948966" velocity="1.57"/>
    <dynamics damping="3.0" friction="0.4"/>
  </joint>
  <transmission name="fingrip_finger2_base_joint_transmission">
    <type>transmission_interface/SimpleTransmission</type>
    <joint name="fingrip_finger2_base_joint">
      <hardwareInterface>hardware_interface/EffortJointInterface</hardwareInterface>
    </joint>
    <actuator name="fingrip_finger2_base_joint_actuator">
      <mechanicalReduction>1</mechanicalReduction>
    </actuator>
  </transmission>
  <gazebo reference="fingrip_finger2_base_joint">
    <springStiffness value="0.0"/>
    <springReference value="0.0"/>
  </gazebo>
  <link name="fingrip_finger2_base_link">
    <visual>
      <origin rpy="0 0 0" xyz="0 0 0"/>
      <geometry>
        <mesh filename="package://fingrip_description/meshes/visual/gripper/base_finger/base_finger.stl"/>
      </geometry>
      <material name="Grey"/>
    </visual>
    <collision>
      <origin rpy="0 0 0" xyz="0 0 0"/>
      <geometry>
        <mesh filename="package://fingrip_description/meshes/collision/gripper/base_finger/base_finger.stl"/>
      </geometry>
    </collision>
    <inertial>
      <origin rpy="0 0 0" xyz="-0.0465 -0.04775 -0.0"/>
      <mass value="0.2238453537819424"/>
      <inertia ixx="0.0007" ixy="-0.0002" ixz="0.0" iyy="0.0006" iyz="0.0" izz="0.0011"/>
    </inertial>
  </link>
  <gazebo reference="fingrip_finger2_base_link">
    <mu1 value="1.13"/>
    <mu2 value="1.13"/>
  </gazebo>
  <joint name="fingrip_finger2_proximal_joint" type="revolute">
    <parent link="fingrip_finger2_base_link"/>
    <child link="fingrip_finger2_proximal_link"/>
    <origin rpy="0 0 0" xyz="0 -0.03255 0"/>
    <axis xyz="0 0 1"/>
    <limit effort="20" lower="-1.3" upper="0.31416" velocity="1.57"/>
    <dynamics damping="3.0" friction="0.4"/>
  </joint>
  <transmission name="fingrip_finger2_proximal_joint_transmission">
    <type>transmission_interface/SimpleTransmission</type>
    <joint name="fingrip_finger2_proximal_joint">
      <hardwareInterface>hardware_interface/EffortJointInterface</hardwareInterface>
    </joint>
    <actuator name="fingrip_finger2_proximal_joint_actuator">
      <mechanicalReduction>1</mechanicalReduction>
    </actuator>
  </transmission>
  <gazebo reference="fingrip_finger2_proximal_joint">
    <springStiffness value="0.0"/>
    <springReference value="0.0"/>
  </gazebo>
  <link name="fingrip_finger2_proximal_link">
    <visual>
      <origin rpy="0 0 0" xyz="0 0 0"/>
      <geometry>
        <mesh filename="package://fingrip_description/meshes/visual/gripper/proximal/short/proximal.stl"/>
      </geometry>
      <material name="Grey"/>
    </visual>
    <collision>
      <origin rpy="0 0 0" xyz="0 0 0"/>
      <geometry>
        <mesh filename="package://fingrip_description/meshes/collision/gripper/proximal/short/proximal.stl"/>
      </geometry>
    </collision>
    <inertial>
      <origin rpy="0 0 0" xyz="0.03411 -0.01012 0.0"/>
      <mass value="0.150"/>
      <inertia ixx="0.000092" ixy="-0.000061" ixz="0.0" iyy="0.00031" iyz="0.0" izz="0.00031"/>
    </inertial>
  </link>
  <gazebo reference="fingrip_finger2_proximal_link">
    <mu1 value="1.13"/>
    <mu2 value="1.13"/>
  </gazebo>
  <joint name="fingrip_finger2_intermediaire_joint" type="revolute">
    <parent link="fingrip_finger2_proximal_link"/>
    <child link="fingrip_finger2_intermediaire_link"/>
    <origin rpy="0 0 0" xyz="0.08 0 0"/>
    <axis xyz="0 0 1"/>
    <limit effort="20" lower="-0.5" upper="1.0472" velocity="1.57"/>
    <dynamics damping="3.0" friction="0.4"/>
  </joint>
  <transmission name="fingrip_finger2_intermediaire_joint_transmission">
    <type>transmission_interface/SimpleTransmission</type>
    <joint name="fingrip_finger2_intermediaire_joint">
      <hardwareInterface>hardware_interface/EffortJointInterface</hardwareInterface>
    </joint>
    <actuator name="fingrip_finger2_intermediaire_joint_actuator">
      <mechanicalReduction>1</mechanicalReduction>
    </actuator>
  </transmission>
  <gazebo reference="fingrip_finger2_intermediaire_joint">
    <springStiffness value="0.0"/>
    <springReference value="0.0"/>
  </gazebo>
  <link name="fingrip_finger2_intermediaire_link">
    <visual>
      <origin rpy="0 0 0" xyz="0 0 0"/>
      <geometry>
        <mesh filename="package://fingrip_description/meshes/visual/gripper/intermediaire/short/intermediaire.stl"/>
      </geometry>
      <material name="Grey"/>
    </visual>
    <collision>
      <origin rpy="0 0 0" xyz="0 0 0"/>
      <geometry>
        <mesh filename="package://fingrip_description/meshes/collision/gripper/intermediaire/short/intermediaire.stl"/>
      </geometry>
    </collision>
    <inertial>
      <origin rpy="0 0 0" xyz="0.01791 -0.01023 0.0"/>
      <mass value="0.150"/>
      <inertia ixx="0.000025" ixy="0.000013" ixz="0.0" iyy="0.000102" iyz="0.0" izz="0.000108"/>
    </inertial>
  </link>
  <gazebo reference="fingrip_finger2_intermediaire_link">
    <mu1 value="1.13"/>
    <mu2 value="1.13"/>
  </gazebo>
  <!-- DISTAL limb -->
  <!--
        <xacro:fingrip_joint
        parent="${prefix}${finger_name}${intermediaire_prefix}${link_prefix}"
        child="${prefix}${finger_name}${distal_prefix}${link_prefix}"
        joint_name="${prefix}${finger_name}${distal_prefix}${joint_prefix}"
        joint_type="${joint_other_type}"
        joint_origin_xyz="${joint_other_origin_xyz}"
        joint_origin_rpy="${joint_other_origin_rpy}"
        joint_axis_xyz="${joint_other_axis_xyz}"
        joint_lower_limit="${joint_lower_limit}"
        joint_upper_limit="${joint_upper_limit}"
        joint_velocity_limit="${joint_velocity_limit}"
        joint_torque_limit="${joint_torque_limit}"
        joint_damping="${joint_damping}"
        joint_friction="${joint_friction}"
        gazebo_preserve_fixed_joint="${gazebo_preserve_fixed_joint}"
        />

        <xacro:fingrip_link
        link_name="${prefix}${finger_name}${distal_prefix}${link_prefix}"
        mesh="${distal_mesh_path}${short_prefix}${distal_mesh_name}"
        collision="${collision}"
        mu="${link_mu}"
        />
        -->
  <joint name="fingrip_finger3_base_joint" type="fixed">
    <parent link="fingrip_hand"/>
    <child link="fingrip_finger3_base_link"/>
    <origin rpy="-1.5707963267948966 -1.5707963267948966 0" xyz="-0.04398 0 0.09885097"/>
  </joint>
  <gazebo reference="fingrip_finger3_base_joint">
    <preserveFixedJoint>true</preserveFixedJoint>
    <disableFixedJointLumping>true</disableFixedJointLumping>
  </gazebo>
  <link name="fingrip_finger3_base_link">
    <visual>
      <origin rpy="0 0 0" xyz="0 0 0"/>
      <geometry>
        <mesh filename="package://fingrip_description/meshes/visual/gripper/base_finger/base_finger.stl"/>
      </geometry>
      <material name="Grey"/>
    </visual>
    <collision>
      <origin rpy="0 0 0" xyz="0 0 0"/>
      <geometry>
        <mesh filename="package://fingrip_description/meshes/collision/gripper/base_finger/base_finger.stl"/>
      </geometry>
    </collision>
    <inertial>
      <origin rpy="0 0 0" xyz="-0.0465 -0.04775 -0.0"/>
      <mass value="0.2238453537819424"/>
      <inertia ixx="0.0007" ixy="-0.0002" ixz="0.0" iyy="0.0006" iyz="0.0" izz="0.0011"/>
    </inertial>
  </link>
  <gazebo reference="fingrip_finger3_base_link">
    <mu1 value="1.13"/>
    <mu2 value="1.13"/>
  </gazebo>
  <joint name="fingrip_finger3_proximal_joint" type="revolute">
    <parent link="fingrip_finger3_base_link"/>
    <child link="fingrip_finger3_proximal_link"/>
    <origin rpy="0 0 0" xyz="0 -0.03255 0"/>
    <axis xyz="0 0 1"/>
    <limit effort="20" lower="-1.3" upper="0.31416" velocity="1.57"/>
    <dynamics damping="3.0" friction="0.4"/>
  </joint>
  <transmission name="fingrip_finger3_proximal_joint_transmission">
    <type>transmission_interface/SimpleTransmission</type>
    <joint name="fingrip_finger3_proximal_joint">
      <hardwareInterface>hardware_interface/EffortJointInterface</hardwareInterface>
    </joint>
    <actuator name="fingrip_finger3_proximal_joint_actuator">
      <mechanicalReduction>1</mechanicalReduction>
    </actuator>
  </transmission>
  <gazebo reference="fingrip_finger3_proximal_joint">
    <springStiffness value="0.0"/>
    <springReference value="0.0"/>
  </gazebo>
  <link name="fingrip_finger3_proximal_link">
    <visual>
      <origin rpy="0 0 0" xyz="0 0 0"/>
      <geometry>
        <mesh filename="package://fingrip_description/meshes/visual/gripper/proximal/short/proximal.stl"/>
      </geometry>
      <material name="Grey"/>
    </visual>
    <collision>
      <origin rpy="0 0 0" xyz="0 0 0"/>
      <geometry>
        <mesh filename="package://fingrip_description/meshes/collision/gripper/proximal/short/proximal.stl"/>
      </geometry>
    </collision>
    <inertial>
      <origin rpy="0 0 0" xyz="0.03411 -0.01012 0.0"/>
      <mass value="0.150"/>
      <inertia ixx="0.000092" ixy="-0.000061" ixz="0.0" iyy="0.00031" iyz="0.0" izz="0.00031"/>
    </inertial>
  </link>
  <gazebo reference="fingrip_finger3_proximal_link">
    <mu1 value="1.13"/>
    <mu2 value="1.13"/>
  </gazebo>
  <joint name="fingrip_finger3_intermediaire_joint" type="revolute">
    <parent link="fingrip_finger3_proximal_link"/>
    <child link="fingrip_finger3_intermediaire_link"/>
    <origin rpy="0 0 0" xyz="0.08 0 0"/>
    <axis xyz="0 0 1"/>
    <limit effort="20" lower="-0.5" upper="1.0472" velocity="1.57"/>
    <dynamics damping="3.0" friction="0.4"/>
  </joint>
  <transmission name="fingrip_finger3_intermediaire_joint_transmission">
    <type>transmission_interface/SimpleTransmission</type>
    <joint name="fingrip_finger3_intermediaire_joint">
      <hardwareInterface>hardware_interface/EffortJointInterface</hardwareInterface>
    </joint>
    <actuator name="fingrip_finger3_intermediaire_joint_actuator">
      <mechanicalReduction>1</mechanicalReduction>
    </actuator>
  </transmission>
  <gazebo reference="fingrip_finger3_intermediaire_joint">
    <springStiffness value="0.0"/>
    <springReference value="0.0"/>
  </gazebo>
  <link name="fingrip_finger3_intermediaire_link">
    <visual>
      <origin rpy="0 0 0" xyz="0 0 0"/>
      <geometry>
        <mesh filename="package://fingrip_description/meshes/visual/gripper/intermediaire/short/intermediaire.stl"/>
      </geometry>
      <material name="Grey"/>
    </visual>
    <collision>
      <origin rpy="0 0 0" xyz="0 0 0"/>
      <geometry>
        <mesh filename="package://fingrip_description/meshes/collision/gripper/intermediaire/short/intermediaire.stl"/>
      </geometry>
    </collision>
    <inertial>
      <origin rpy="0 0 0" xyz="0.01791 -0.01023 0.0"/>
      <mass value="0.150"/>
      <inertia ixx="0.000025" ixy="0.000013" ixz="0.0" iyy="0.000102" iyz="0.0" izz="0.000108"/>
    </inertial>
  </link>
  <gazebo reference="fingrip_finger3_intermediaire_link">
    <mu1 value="1.13"/>
    <mu2 value="1.13"/>
  </gazebo>
  <!-- DISTAL limb -->
  <!--
        <xacro:fingrip_joint
        parent="${prefix}${finger_name}${intermediaire_prefix}${link_prefix}"
        child="${prefix}${finger_name}${distal_prefix}${link_prefix}"
        joint_name="${prefix}${finger_name}${distal_prefix}${joint_prefix}"
        joint_type="${joint_other_type}"
        joint_origin_xyz="${joint_other_origin_xyz}"
        joint_origin_rpy="${joint_other_origin_rpy}"
        joint_axis_xyz="${joint_other_axis_xyz}"
        joint_lower_limit="${joint_lower_limit}"
        joint_upper_limit="${joint_upper_limit}"
        joint_velocity_limit="${joint_velocity_limit}"
        joint_torque_limit="${joint_torque_limit}"
        joint_damping="${joint_damping}"
        joint_friction="${joint_friction}"
        gazebo_preserve_fixed_joint="${gazebo_preserve_fixed_joint}"
        />

        <xacro:fingrip_link
        link_name="${prefix}${finger_name}${distal_prefix}${link_prefix}"
        mesh="${distal_mesh_path}${short_prefix}${distal_mesh_name}"
        collision="${collision}"
        mu="${link_mu}"
        />
        -->
  <link name="fingrip_hand_tcp">
  </link>
  <joint name="fingrip_hand_tcp_virtual_joint" type="fixed">
    <parent link="fingrip_hand"/>
    <child link="fingrip_hand_tcp"/>
    <origin rpy="0 0 0" xyz="0 0 0.12"/>
  </joint>
  <ros2_control name="fingrip_gripper_system" type="system">
    <hardware>
      <plugin>gz_ros2_control/GazeboSimSystem</plugin>
    </hardware>
    <joint name="fingrip_finger1_base_joint">
      <param name="initial_position">0.0</param>
      <command_interface name="effort"/>
      <state_interface name="position"/>
      <state_interface name="velocity"/>
      <state_interface name="effort"/>
    </joint>
    <joint name="fingrip_finger1_proximal_joint">
      <param name="initial_position">-1.29</param>
      <command_interface name="effort"/>
      <state_interface name="position"/>
      <state_interface name="velocity"/>
      <state_interface name="effort"/>
    </joint>
    <joint name="fingrip_finger1_intermediaire_joint">
      <param name="initial_position">-0.5</param>
      <command_interface name="effort"/>
      <state_interface name="position"/>
      <state_interface name="velocity"/>
      <state_interface name="effort"/>
    </joint>
    <hardware>
      <plugin>gz_ros2_control/GazeboSimSystem</plugin>
    </hardware>
    <joint name="fingrip_finger2_base_joint">
      <param name="initial_position">0.0</param>
      <command_interface name="effort"/>
      <state_interface name="position"/>
      <state_interface name="velocity"/>
      <state_interface name="effort"/>
    </joint>
    <joint name="fingrip_finger2_proximal_joint">
      <param name="initial_position">-1.29</param>
      <command_interface name="effort"/>
      <state_interface name="position"/>
      <state_interface name="velocity"/>
      <state_interface name="effort"/>
    </joint>
    <joint name="fingrip_finger2_intermediaire_joint">
      <param name="initial_position">-0.5</param>
      <command_interface name="effort"/>
      <state_interface name="position"/>
      <state_interface name="velocity"/>
      <state_interface name="effort"/>
    </joint>
    <hardware>
      <plugin>gz_ros2_control/GazeboSimSystem</plugin>
    </hardware>
    <joint name="fingrip_finger3_proximal_joint">
      <param name="initial_position">-1.29</param>
      <command_interface name="effort"/>
      <state_interface name="position"/>
      <state_interface name="velocity"/>
      <state_interface name="effort"/>
    </joint>
    <joint name="fingrip_finger3_intermediaire_joint">
      <param name="initial_position">-0.5</param>
      <command_interface name="effort"/>
      <state_interface name="position"/>
      <state_interface name="velocity"/>
      <state_interface name="effort"/>
    </joint>
  </ros2_control>
  <gazebo>
    <plugin filename="libgz_ros2_control-system" name="gz_ros2_control::GazeboSimROS2ControlPlugin">
      <parameters>/home/alex/additive_manufacturing/Planner4grasping/install/share/fingrip_moveit_config/config/controllers_effort.yaml</parameters>
    </plugin>
  </gazebo>
</robot>
