<sdf version='1.10'>
  <model name='fingrip'>
    <joint name='fingrip_joint_base' type='fixed'>
      <pose relative_to='__model__'>0 0 0 0 0 0</pose>
      <parent>world</parent>
      <child>fingrip_link0</child>
    </joint>
    <link name='fingrip_link0'>
      <pose relative_to='fingrip_joint_base'>0 0 0 0 0 0</pose>
      <inertial>
        <pose>-0.10000000000000001 0 0.070000000000000007 0 0 0</pose>
        <mass>2.8142713001040618</mass>
        <inertia>
          <ixx>0.0075390636364814686</ixx>
          <ixy>-1.505312457478333e-05</ixy>
          <ixz>-0.0012144328835738971</ixz>
          <iyy>0.01050801742738296</iyy>
          <iyz>1.043480350103298e-05</iyz>
          <izz>0.0098649336387082748</izz>
        </inertia>
      </inertial>
      <collision name='fingrip_link0_collision'>
        <pose>0 0 0 0 0 0</pose>
        <geometry>
          <mesh>
            <scale>1 1 1</scale>
            <uri>meshes/collision/arm/link0.stl</uri>
          </mesh>
        </geometry>
        <surface>
          <contact>
            <ode/>
          </contact>
          <friction>
            <ode>
              <mu>0.84999999999999998</mu>
              <mu2>0.84999999999999998</mu2>
            </ode>
          </friction>
        </surface>
      </collision>
      <visual name='fingrip_link0_visual'>
        <pose>0 0 0 0 0 0</pose>
        <geometry>
          <mesh>
            <scale>1 1 1</scale>
            <uri>meshes/visual/arm/link0.stl</uri>
          </mesh>
        </geometry>
        <material>
          <diffuse>0.25 0.25 0.25 1</diffuse>
          <ambient>0.25 0.25 0.25 1</ambient>
        </material>
      </visual>
    </link>
    <joint name='fingrip_joint1' type='revolute'>
      <pose relative_to='fingrip_link0'>0 0 0.1575 0 0 0</pose>
      <parent>fingrip_link0</parent>
      <child>fingrip_link1</child>
      <axis>
        <xyz>0 0 1</xyz>
        <limit>
          <lower>-2.9670597283903599</lower>
          <upper>2.9670597283903599</upper>
          <effort>87</effort>
          <velocity>1.48352986419518</velocity>
        </limit>
        <dynamics>
          <damping>21.75</damping>
          <friction>3.48</friction>
          <spring_reference>0</spring_reference>
          <spring_stiffness>0</spring_stiffness>
        </dynamics>
      </axis>
      <physics>
        <ode>
          <limit>
            <cfm>0</cfm>
            <erp>0.20000000000000001</erp>
          </limit>
        </ode>
      </physics>
    </joint>
    <link name='fingrip_link1'>
      <pose relative_to='fingrip_joint1'>0 0 0 0 0 0</pose>
      <inertial>
        <pose>0 -0.029999999999999999 0.12 0 0 0</pose>
        <mass>2.6433170427227211</mass>
        <inertia>
          <ixx>0.017405076982879721</ixx>
          <ixy>-8.6879863696210777e-09</ixy>
          <ixz>-1.627781906292042e-08</ixz>
          <iyy>0.01535207793578173</iyy>
          <iyz>0.0045108559591022449</iyz>
          <izz>0.0059878916630738566</izz>
        </inertia>
      </inertial>
      <collision name='fingrip_link1_collision'>
        <pose>0 0 0 0 0 0</pose>
        <geometry>
          <mesh>
            <scale>1 1 1</scale>
            <uri>meshes/collision/arm/link1.stl</uri>
          </mesh>
        </geometry>
        <surface>
          <contact>
            <ode/>
          </contact>
          <friction>
            <ode>
              <mu>0.84999999999999998</mu>
              <mu2>0.84999999999999998</mu2>
            </ode>
          </friction>
        </surface>
      </collision>
      <visual name='fingrip_link1_visual'>
        <pose>0 0 0 0 0 0</pose>
        <geometry>
          <mesh>
            <scale>1 1 1</scale>
            <uri>meshes/visual/arm/link1.stl</uri>
          </mesh>
        </geometry>
        <material>
          <diffuse>0.625 0.875 1 1</diffuse>
          <ambient>0.625 0.875 1 1</ambient>
        </material>
      </visual>
    </link>
    <joint name='fingrip_joint2' type='revolute'>
      <pose relative_to='fingrip_link1'>0 0 0.20250000000000001 1.5707963267948959 0 -3.1415926535897931</pose>
      <parent>fingrip_link1</parent>
      <child>fingrip_link2</child>
      <axis>
        <xyz>0 0 1</xyz>
        <limit>
          <lower>-2.0943951023931948</lower>
          <upper>2.0943951023931948</upper>
          <effort>87</effort>
          <velocity>1.48352986419518</velocity>
        </limit>
        <dynamics>
          <damping>21.75</damping>
          <friction>3.48</friction>
          <spring_reference>0</spring_reference>
          <spring_stiffness>0</spring_stiffness>
        </dynamics>
      </axis>
      <physics>
        <ode>
          <limit>
            <cfm>0</cfm>
            <erp>0.20000000000000001</erp>
          </limit>
        </ode>
      </physics>
    </joint>
    <link name='fingrip_link2'>
      <pose relative_to='fingrip_joint2'>0 0 0 0 0 0</pose>
      <inertial>
        <pose>0.00029 0.058999999999999997 0.042000000000000003 0 0 0</pose>
        <mass>2.6652755331661191</mass>
        <inertia>
          <ixx>0.017786940056353829</ixx>
          <ixy>8.7063562587911901e-08</ixy>
          <ixz>3.7520720583940079e-08</ixz>
          <iyy>0.0060441338679528443</iyy>
          <iyz>-0.0045994902954903756</iyz>
          <izz>0.015710955004556951</izz>
        </inertia>
      </inertial>
      <collision name='fingrip_link2_collision'>
        <pose>0 0 0 0 0 0</pose>
        <geometry>
          <mesh>
            <scale>1 1 1</scale>
            <uri>meshes/collision/arm/link2.stl</uri>
          </mesh>
        </geometry>
        <surface>
          <contact>
            <ode/>
          </contact>
          <friction>
            <ode>
              <mu>0.84999999999999998</mu>
              <mu2>0.84999999999999998</mu2>
            </ode>
          </friction>
        </surface>
      </collision>
      <visual name='fingrip_link2_visual'>
        <pose>0 0 0 0 0 0</pose>
        <geometry>
          <mesh>
            <scale>1 1 1</scale>
            <uri>meshes/visual/arm/link2.stl</uri>
          </mesh>
        </geometry>
        <material>
          <diffuse>0.625 0.875 1 1</diffuse>
          <ambient>0.625 0.875 1 1</ambient>
        </material>
      </visual>
    </link>
    <joint name='fingrip_joint3' type='revolute'>
      <pose relative_to='fingrip_link2'>0 0.20449999999999999 0 1.5707963267948959 0 -3.1415926535897931</pose>
      <parent>fingrip_link2</parent>
      <child>fingrip_link3</child>
      <axis>
        <xyz>0 0 1</xyz>
        <limit>
          <lower>-2.9670597283903599</lower>
          <upper>2.9670597283903599</upper>
          <effort>87</effort>
          <velocity>1.74532925199433</velocity>
        </limit>
        <dynamics>
          <damping>21.75</damping>
          <friction>3.48</friction>
          <spring_reference>0</spring_reference>
          <spring_stiffness>0</spring_stiffness>
        </dynamics>
      </axis>
      <physics>
        <ode>
          <limit>
            <cfm>0</cfm>
            <erp>0.20000000000000001</erp>
          </limit>
        </ode>
      </physics>
    </joint>
    <link name='fingrip_link3'>
      <pose relative_to='fingrip_joint3'>0 0 0 0 0 0</pose>
      <inertial>
        <pose>0 0.029999999999999999 0.13 0 0 0</pose>
        <mass>2.3293714829045729</mass>
        <inertia>
          <ixx>0.0075496764161139774</ixx>
          <ixy>-0.002432046451349223</ixy>
          <ixz>-0.003250815048103007</ixz>
          <iyy>0.0096806760801913978</iyy>
          <iyz>-0.0021316282421730689</iyz>
          <izz>0.0079445574220080861</izz>
        </inertia>
      </inertial>
      <collision name='fingrip_link3_collision'>
        <pose>0 0 0 0 0 0</pose>
        <geometry>
          <mesh>
            <scale>1 1 1</scale>
            <uri>meshes/collision/arm/link3.stl</uri>
          </mesh>
        </geometry>
        <surface>
          <contact>
            <ode/>
          </contact>
          <friction>
            <ode>
              <mu>0.84999999999999998</mu>
              <mu2>0.84999999999999998</mu2>
            </ode>
          </friction>
        </surface>
      </collision>
      <visual name='fingrip_link3_visual'>
        <pose>0 0 0 0 0 0</pose>
        <geometry>
          <mesh>
            <scale>1 1 1</scale>
            <uri>meshes/visual/arm/link3.stl</uri>
          </mesh>
        </geometry>
        <material>
          <diffuse>1 0.529411793 0.0490196086 1</diffuse>
          <ambient>1 0.529411793 0.0490196086 1</ambient>
        </material>
      </visual>
    </link>
    <joint name='fingrip_joint4' type='revolute'>
      <pose relative_to='fingrip_link3'>0 0 0.2155 1.5707963267948959 0 0</pose>
      <parent>fingrip_link3</parent>
      <child>fingrip_link4</child>
      <axis>
        <xyz>0 0 1</xyz>
        <limit>
          <lower>-2.0943951023931948</lower>
          <upper>2.0943951023931948</upper>
          <effort>87</effort>
          <velocity>1.308996938995747</velocity>
        </limit>
        <dynamics>
          <damping>21.75</damping>
          <friction>3.48</friction>
          <spring_reference>0</spring_reference>
          <spring_stiffness>0</spring_stiffness>
        </dynamics>
      </axis>
      <physics>
        <ode>
          <limit>
            <cfm>0</cfm>
            <erp>0.20000000000000001</erp>
          </limit>
        </ode>
      </physics>
    </joint>
    <link name='fingrip_link4'>
      <pose relative_to='fingrip_joint4'>0 0 0 0 0 0</pose>
      <inertial>
        <pose>0 0.067000000000000004 0.034000000000000002 0 0 0</pose>
        <mass>2.3104763646281512</mass>
        <inertia>
          <ixx>0.0077645688148648279</ixx>
          <ixy>0.0033714752040459352</ixy>
          <ixz>-0.0023436211131682479</ixz>
          <iyy>0.0080157769299801489</iyy>
          <iyz>0.002291752616147062</iyz>
          <izz>0.0099558823080710662</izz>
        </inertia>
      </inertial>
      <collision name='fingrip_link4_collision'>
        <pose>0 0 0 0 0 0</pose>
        <geometry>
          <mesh>
            <scale>1 1 1</scale>
            <uri>meshes/collision/arm/link4.stl</uri>
          </mesh>
        </geometry>
        <surface>
          <contact>
            <ode/>
          </contact>
          <friction>
            <ode>
              <mu>0.84999999999999998</mu>
              <mu2>0.84999999999999998</mu2>
            </ode>
          </friction>
        </surface>
      </collision>
      <visual name='fingrip_link4_visual'>
        <pose>0 0 0 0 0 0</pose>
        <geometry>
          <mesh>
            <scale>1 1 1</scale>
            <uri>meshes/visual/arm/link4.stl</uri>
          </mesh>
        </geometry>
        <material>
          <diffuse>0.625 0.875 1 1</diffuse>
          <ambient>0.625 0.875 1 1</ambient>
        </material>
      </visual>
    </link>
    <joint name='fingrip_joint5' type='revolute'>
      <pose relative_to='fingrip_link4'>0 0.1845 0 1.5707963267948959 0 3.1415926535897931</pose>
      <parent>fingrip_link4</parent>
      <child>fingrip_link5</child>
      <axis>
        <xyz>0 0 1</xyz>
        <limit>
          <lower>-2.9670597283903599</lower>
          <upper>2.9670597283903599</upper>
          <effort>12</effort>
          <velocity>2.268928027592628</velocity>
        </limit>
        <dynamics>
          <damping>3</damping>
          <friction>0.47999999999999998</friction>
          <spring_reference>0</spring_reference>
          <spring_stiffness>0</spring_stiffness>
        </dynamics>
      </axis>
      <physics>
        <ode>
          <limit>
            <cfm>0</cfm>
            <erp>0.20000000000000001</erp>
          </limit>
        </ode>
      </physics>
    </joint>
    <link name='fingrip_link5'>
      <pose relative_to='fingrip_joint5'>0 0 0 0 0 0</pose>
      <inertial>
        <pose>0.0001 0.021000000000000001 0.075999999999999998 0 0 0</pose>
        <mass>2.6226426154892</mass>
        <inertia>
          <ixx>0.029070538014399381</ixx>
          <ixy>6.2087382687255679e-07</ixy>
          <ixz>-1.005915192502339e-05</ixz>
          <iyy>0.027638529986528791</iyy>
          <iyz>-0.0074243064778508139</iyz>
          <izz>0.0042511112344007368</izz>
        </inertia>
      </inertial>
      <collision name='fingrip_link5_collision'>
        <pose>0 0 0 0 0 0</pose>
        <geometry>
          <mesh>
            <scale>1 1 1</scale>
            <uri>meshes/collision/arm/link5.stl</uri>
          </mesh>
        </geometry>
        <surface>
          <contact>
            <ode/>
          </contact>
          <friction>
            <ode>
              <mu>0.84999999999999998</mu>
              <mu2>0.84999999999999998</mu2>
            </ode>
          </friction>
        </surface>
      </collision>
      <visual name='fingrip_link5_visual'>
        <pose>0 0 0 0 0 0</pose>
        <geometry>
          <mesh>
            <scale>1 1 1</scale>
            <uri>meshes/visual/arm/link5.stl</uri>
          </mesh>
        </geometry>
        <material>
          <diffuse>0.625 0.875 1 1</diffuse>
          <ambient>0.625 0.875 1 1</ambient>
        </material>
      </visual>
    </link>
    <joint name='fingrip_joint6' type='revolute'>
      <pose relative_to='fingrip_link5'>0 0 0.2155 1.5707963267948959 0 0</pose>
      <parent>fingrip_link5</parent>
      <child>fingrip_link6</child>
      <axis>
        <xyz>0 0 1</xyz>
        <limit>
          <lower>-2.0943951023931948</lower>
          <upper>2.0943951023931948</upper>
          <effort>12</effort>
          <velocity>2.3561944901923448</velocity>
        </limit>
        <dynamics>
          <damping>3</damping>
          <friction>0.47999999999999998</friction>
          <spring_reference>0</spring_reference>
          <spring_stiffness>0</spring_stiffness>
        </dynamics>
      </axis>
      <physics>
        <ode>
          <limit>
            <cfm>0</cfm>
            <erp>0.20000000000000001</erp>
          </limit>
        </ode>
      </physics>
    </joint>
    <link name='fingrip_link6'>
      <pose relative_to='fingrip_joint6'>0 0 0 0 0 0</pose>
      <inertial>
        <pose>0 0.00059000000000000003 0.00040000000000000002 0 0 0</pose>
        <mass>1.502580488662679</mass>
        <inertia>
          <ixx>0.002940555801469018</ixx>
          <ixy>-0.00042391108351381513</ixy>
          <ixz>0.00061000773533871698</ixz>
          <iyy>0.0039210520124867698</iyy>
          <iyz>0.00012647545430836209</iyz>
          <izz>0.0054115603870960186</izz>
        </inertia>
      </inertial>
      <collision name='fingrip_link6_collision'>
        <pose>0 0 0 0 0 0</pose>
        <geometry>
          <mesh>
            <scale>1 1 1</scale>
            <uri>meshes/collision/arm/link6.stl</uri>
          </mesh>
        </geometry>
        <surface>
          <contact>
            <ode/>
          </contact>
          <friction>
            <ode>
              <mu>0.84999999999999998</mu>
              <mu2>0.84999999999999998</mu2>
            </ode>
          </friction>
        </surface>
      </collision>
      <visual name='fingrip_link6_visual'>
        <pose>0 0 0 0 0 0</pose>
        <geometry>
          <mesh>
            <scale>1 1 1</scale>
            <uri>meshes/visual/arm/link6.stl</uri>
          </mesh>
        </geometry>
        <material>
          <diffuse>1 0.529411793 0.0490196086 1</diffuse>
          <ambient>1 0.529411793 0.0490196086 1</ambient>
        </material>
      </visual>
    </link>
    <joint name='fingrip_joint7' type='revolute'>
      <pose relative_to='fingrip_link6'>0 0.081000000000000003 0 1.5707963267948959 0 -3.1415926535897931</pose>
      <parent>fingrip_link6</parent>
      <child>fingrip_link7</child>
      <axis>
        <xyz>0 0 1</xyz>
        <limit>
          <lower>-3.0543261909900759</lower>
          <upper>3.0543261909900759</upper>
          <effort>12</effort>
          <velocity>2.3561944901923448</velocity>
        </limit>
        <dynamics>
          <damping>3</damping>
          <friction>0.47999999999999998</friction>
          <spring_reference>0</spring_reference>
          <spring_stiffness>0</spring_stiffness>
        </dynamics>
      </axis>
      <physics>
        <ode>
          <limit>
            <cfm>0</cfm>
            <erp>0.20000000000000001</erp>
          </limit>
        </ode>
      </physics>
    </joint>
    <link name='fingrip_link7'>
      <pose relative_to='fingrip_joint7'>0 0 0 0 0 0</pose>
      <inertial>
        <pose>0 0 0.05327881502382277 0 0 0</pose>
        <mass>0.80498211603839565</mass>
        <inertia>
          <ixx>0.0038602795137068291</ixx>
          <ixy>-0.0001186748917983392</ixy>
          <ixz>3.8619624606881357e-05</ixz>
          <iyy>0.0029404550443006112</iyy>
          <iyz>-9.0484793495320919e-05</iyz>
          <izz>0.0016837493162008049</izz>
        </inertia>
      </inertial>
      <collision name='fingrip_link7_collision'>
        <pose>0 0 0 0 0 0</pose>
        <geometry>
          <mesh>
            <scale>1 1 1</scale>
            <uri>meshes/collision/arm/link7.stl</uri>
          </mesh>
        </geometry>
        <surface>
          <contact>
            <ode/>
          </contact>
          <friction>
            <ode>
              <mu>0.84999999999999998</mu>
              <mu2>0.84999999999999998</mu2>
            </ode>
          </friction>
        </surface>
      </collision>
      <collision name='fingrip_link7_fixed_joint_lump__fingrip_hand_collision_1'>
        <pose>0 0 0.132936 0 0 0</pose>
        <geometry>
          <mesh>
            <scale>1 1 1</scale>
            <uri>meshes/collision/gripper/paume/base_hand_paume1.stl</uri>
          </mesh>
        </geometry>
        <surface>
          <contact>
            <ode/>
          </contact>
          <friction>
            <ode>
              <mu>0.84999999999999998</mu>
              <mu2>0.84999999999999998</mu2>
            </ode>
          </friction>
        </surface>
      </collision>
      <collision name='fingrip_link7_fixed_joint_lump__fingrip_palm_collision_2'>
        <pose>0 0 0.14593600000000001 0 0 0</pose>
        <geometry>
          <mesh>
            <scale>1 1 1</scale>
            <uri>meshes/collision/gripper/case/case_3d.stl</uri>
          </mesh>
        </geometry>
        <surface>
          <contact>
            <ode/>
          </contact>
          <friction>
            <ode>
              <mu>0.84999999999999998</mu>
              <mu2>0.84999999999999998</mu2>
            </ode>
          </friction>
        </surface>
      </collision>
      <visual name='fingrip_link7_visual'>
        <pose>0 0 0 0 0 0</pose>
        <geometry>
          <mesh>
            <scale>1 1 1</scale>
            <uri>meshes/visual/arm/link7.stl</uri>
          </mesh>
        </geometry>
        <material>
          <diffuse>0.25 0.25 0.25 1</diffuse>
          <ambient>0.25 0.25 0.25 1</ambient>
        </material>
      </visual>
      <visual name='fingrip_link7_fixed_joint_lump__fingrip_hand_visual_1'>
        <pose>0 0 0.132936 0 0 0</pose>
        <geometry>
          <mesh>
            <scale>1 1 1</scale>
            <uri>meshes/visual/gripper/paume/base_hand_paume1.stl</uri>
          </mesh>
        </geometry>
        <material>
          <diffuse>0.25 0.25 0.25 1</diffuse>
          <ambient>0.25 0.25 0.25 1</ambient>
        </material>
      </visual>
      <visual name='fingrip_link7_fixed_joint_lump__fingrip_palm_visual_2'>
        <pose>0 0 0.14593600000000001 0 0 0</pose>
        <geometry>
          <mesh>
            <scale>1 1 1</scale>
            <uri>meshes/visual/gripper/case/case_3d.stl</uri>
          </mesh>
        </geometry>
        <material>
          <diffuse>0.25 0.25 0.25 1</diffuse>
          <ambient>0.25 0.25 0.25 1</ambient>
        </material>
      </visual>
    </link>
    <joint name='fingrip_finger1_base_joint' type='revolute'>
      <pose relative_to='fingrip_link7'>0.053999999999999999 0.053999999999999999 0.23178697000000001 -3.1415926535897931 -1.5707963267948966 0</pose>
      <parent>fingrip_link7</parent>
      <child>fingrip_finger1_base_link</child>
      <axis>
        <xyz>1 0 0</xyz>
        <limit>
          <lower>-1.570796326794897</lower>
          <upper>0</upper>
          <effort>20</effort>
          <velocity>3.1400000000000001</velocity>
        </limit>
        <dynamics>
          <damping>3</damping>
          <friction>0.40000000000000002</friction>
          <spring_reference>0</spring_reference>
          <spring_stiffness>0</spring_stiffness>
        </dynamics>
      </axis>
      <physics>
        <ode>
          <limit>
            <cfm>0</cfm>
            <erp>0.20000000000000001</erp>
          </limit>
        </ode>
      </physics>
    </joint>
    <link name='fingrip_finger1_base_link'>
      <pose relative_to='fingrip_finger1_base_joint'>0 0 0 0 0 0</pose>
      <inertial>
        <pose>-0.0465 -0.047750000000000001 0 0 0 0</pose>
        <mass>0.2238453537819424</mass>
        <inertia>
          <ixx>0.00069999999999999999</ixx>
          <ixy>-0.00020000000000000001</ixy>
          <ixz>0</ixz>
          <iyy>0.00059999999999999995</iyy>
          <iyz>0</iyz>
          <izz>0.0011000000000000001</izz>
        </inertia>
      </inertial>
      <collision name='fingrip_finger1_base_link_collision'>
        <pose>0 0 0 0 0 0</pose>
        <geometry>
          <mesh>
            <scale>1 1 1</scale>
            <uri>meshes/collision/gripper/base_finger/base_finger.stl</uri>
          </mesh>
        </geometry>
        <surface>
          <contact>
            <ode/>
          </contact>
          <friction>
            <ode>
              <mu>1.1299999999999999</mu>
              <mu2>1.1299999999999999</mu2>
            </ode>
          </friction>
        </surface>
      </collision>
      <visual name='fingrip_finger1_base_link_visual'>
        <pose>0 0 0 0 0 0</pose>
        <geometry>
          <mesh>
            <scale>1 1 1</scale>
            <uri>meshes/visual/gripper/base_finger/base_finger.stl</uri>
          </mesh>
        </geometry>
        <material>
          <diffuse>0.25 0.25 0.25 1</diffuse>
          <ambient>0.25 0.25 0.25 1</ambient>
        </material>
      </visual>
    </link>
    <joint name='fingrip_finger1_proximal_joint' type='revolute'>
      <pose relative_to='fingrip_finger1_base_link'>0 -0.032550000000000003 0 0 0 0</pose>
      <parent>fingrip_finger1_base_link</parent>
      <child>fingrip_finger1_proximal_link</child>
      <axis>
        <xyz>0 0 1</xyz>
        <limit>
          <lower>-1.3</lower>
          <upper>0.31415999999999999</upper>
          <effort>20</effort>
          <velocity>0.20000000000000001</velocity>
        </limit>
        <dynamics>
          <damping>3</damping>
          <friction>0.40000000000000002</friction>
          <spring_reference>0</spring_reference>
          <spring_stiffness>0</spring_stiffness>
        </dynamics>
      </axis>
      <physics>
        <ode>
          <limit>
            <cfm>0</cfm>
            <erp>0.20000000000000001</erp>
          </limit>
        </ode>
      </physics>
    </joint>
    <link name='fingrip_finger1_proximal_link'>
      <pose relative_to='fingrip_finger1_proximal_joint'>0 0 0 0 0 0</pose>
      <inertial>
        <pose>0.034110000000000001 -0.010120000000000001 0 0 0 0</pose>
        <mass>0.2238453537819424</mass>
        <inertia>
          <ixx>9.2e-05</ixx>
          <ixy>-6.0999999999999999e-05</ixy>
          <ixz>0</ixz>
          <iyy>0.00031</iyy>
          <iyz>0</iyz>
          <izz>0.00031</izz>
        </inertia>
      </inertial>
      <collision name='fingrip_finger1_proximal_link_collision'>
        <pose>0 0 0 0 0 0</pose>
        <geometry>
          <mesh>
            <scale>1 1 1</scale>
            <uri>meshes/collision/gripper/proximal/short/proximal.stl</uri>
          </mesh>
        </geometry>
        <surface>
          <contact>
            <ode/>
          </contact>
          <friction>
            <ode>
              <mu>1.1299999999999999</mu>
              <mu2>1.1299999999999999</mu2>
            </ode>
          </friction>
        </surface>
      </collision>
      <visual name='fingrip_finger1_proximal_link_visual'>
        <pose>0 0 0 0 0 0</pose>
        <geometry>
          <mesh>
            <scale>1 1 1</scale>
            <uri>meshes/visual/gripper/proximal/short/proximal.stl</uri>
          </mesh>
        </geometry>
        <material>
          <diffuse>0.25 0.25 0.25 1</diffuse>
          <ambient>0.25 0.25 0.25 1</ambient>
        </material>
      </visual>
    </link>
    <joint name='fingrip_finger2_base_joint' type='revolute'>
      <pose relative_to='fingrip_link7'>0.053999999999999999 -0.053999999999999999 0.23178697000000001 -2.4492935982947059e-16 -1.5707963267948966 0</pose>
      <parent>fingrip_link7</parent>
      <child>fingrip_finger2_base_link</child>
      <axis>
        <xyz>1 0 0</xyz>
        <limit>
          <lower>0</lower>
          <upper>1.570796326794897</upper>
          <effort>20</effort>
          <velocity>3.1400000000000001</velocity>
        </limit>
        <dynamics>
          <damping>3</damping>
          <friction>0.40000000000000002</friction>
          <spring_reference>0</spring_reference>
          <spring_stiffness>0</spring_stiffness>
        </dynamics>
      </axis>
      <physics>
        <ode>
          <limit>
            <cfm>0</cfm>
            <erp>0.20000000000000001</erp>
          </limit>
        </ode>
      </physics>
    </joint>
    <link name='fingrip_finger2_base_link'>
      <pose relative_to='fingrip_finger2_base_joint'>0 0 0 0 0 0</pose>
      <inertial>
        <pose>-0.0465 -0.047750000000000001 0 0 0 0</pose>
        <mass>0.2238453537819424</mass>
        <inertia>
          <ixx>0.00069999999999999999</ixx>
          <ixy>-0.00020000000000000001</ixy>
          <ixz>0</ixz>
          <iyy>0.00059999999999999995</iyy>
          <iyz>0</iyz>
          <izz>0.0011000000000000001</izz>
        </inertia>
      </inertial>
      <collision name='fingrip_finger2_base_link_collision'>
        <pose>0 0 0 0 0 0</pose>
        <geometry>
          <mesh>
            <scale>1 1 1</scale>
            <uri>meshes/collision/gripper/base_finger/base_finger.stl</uri>
          </mesh>
        </geometry>
        <surface>
          <contact>
            <ode/>
          </contact>
          <friction>
            <ode>
              <mu>1.1299999999999999</mu>
              <mu2>1.1299999999999999</mu2>
            </ode>
          </friction>
        </surface>
      </collision>
      <visual name='fingrip_finger2_base_link_visual'>
        <pose>0 0 0 0 0 0</pose>
        <geometry>
          <mesh>
            <scale>1 1 1</scale>
            <uri>meshes/visual/gripper/base_finger/base_finger.stl</uri>
          </mesh>
        </geometry>
        <material>
          <diffuse>0.25 0.25 0.25 1</diffuse>
          <ambient>0.25 0.25 0.25 1</ambient>
        </material>
      </visual>
    </link>
    <joint name='fingrip_finger2_proximal_joint' type='revolute'>
      <pose relative_to='fingrip_finger2_base_link'>0 -0.032550000000000003 0 0 0 0</pose>
      <parent>fingrip_finger2_base_link</parent>
      <child>fingrip_finger2_proximal_link</child>
      <axis>
        <xyz>0 0 1</xyz>
        <limit>
          <lower>-1.3</lower>
          <upper>0.31415999999999999</upper>
          <effort>20</effort>
          <velocity>0.20000000000000001</velocity>
        </limit>
        <dynamics>
          <damping>3</damping>
          <friction>0.40000000000000002</friction>
          <spring_reference>0</spring_reference>
          <spring_stiffness>0</spring_stiffness>
        </dynamics>
      </axis>
      <physics>
        <ode>
          <limit>
            <cfm>0</cfm>
            <erp>0.20000000000000001</erp>
          </limit>
        </ode>
      </physics>
    </joint>
    <link name='fingrip_finger2_proximal_link'>
      <pose relative_to='fingrip_finger2_proximal_joint'>0 0 0 0 0 0</pose>
      <inertial>
        <pose>0.034110000000000001 -0.010120000000000001 0 0 0 0</pose>
        <mass>0.2238453537819424</mass>
        <inertia>
          <ixx>9.2e-05</ixx>
          <ixy>-6.0999999999999999e-05</ixy>
          <ixz>0</ixz>
          <iyy>0.00031</iyy>
          <iyz>0</iyz>
          <izz>0.00031</izz>
        </inertia>
      </inertial>
      <collision name='fingrip_finger2_proximal_link_collision'>
        <pose>0 0 0 0 0 0</pose>
        <geometry>
          <mesh>
            <scale>1 1 1</scale>
            <uri>meshes/collision/gripper/proximal/short/proximal.stl</uri>
          </mesh>
        </geometry>
        <surface>
          <contact>
            <ode/>
          </contact>
          <friction>
            <ode>
              <mu>1.1299999999999999</mu>
              <mu2>1.1299999999999999</mu2>
            </ode>
          </friction>
        </surface>
      </collision>
      <visual name='fingrip_finger2_proximal_link_visual'>
        <pose>0 0 0 0 0 0</pose>
        <geometry>
          <mesh>
            <scale>1 1 1</scale>
            <uri>meshes/visual/gripper/proximal/short/proximal.stl</uri>
          </mesh>
        </geometry>
        <material>
          <diffuse>0.25 0.25 0.25 1</diffuse>
          <ambient>0.25 0.25 0.25 1</ambient>
        </material>
      </visual>
    </link>
    <joint name='fingrip_finger3_base_joint' type='fixed'>
      <pose relative_to='fingrip_link7'>-0.043979999999999998 0 0.23178697000000001 -1.5707963267948957 -1.5707963267948966 0</pose>
      <parent>fingrip_link7</parent>
      <child>fingrip_finger3_base_link</child>
      <axis>
        <dynamics>
          <spring_reference>0</spring_reference>
          <spring_stiffness>0</spring_stiffness>
        </dynamics>
        <xyz>0 0 1</xyz>
        <limit>
          <lower>-inf</lower>
          <upper>inf</upper>
        </limit>
      </axis>
      <physics>
        <ode>
          <limit>
            <cfm>0</cfm>
            <erp>0.20000000000000001</erp>
          </limit>
        </ode>
      </physics>
    </joint>
    <link name='fingrip_finger3_base_link'>
      <pose relative_to='fingrip_finger3_base_joint'>0 0 0 0 0 0</pose>
      <inertial>
        <pose>-0.0465 -0.047750000000000001 0 0 0 0</pose>
        <mass>0.2238453537819424</mass>
        <inertia>
          <ixx>0.00069999999999999999</ixx>
          <ixy>-0.00020000000000000001</ixy>
          <ixz>0</ixz>
          <iyy>0.00059999999999999995</iyy>
          <iyz>0</iyz>
          <izz>0.0011000000000000001</izz>
        </inertia>
      </inertial>
      <collision name='fingrip_finger3_base_link_collision'>
        <pose>0 0 0 0 0 0</pose>
        <geometry>
          <mesh>
            <scale>1 1 1</scale>
            <uri>meshes/collision/gripper/base_finger/base_finger.stl</uri>
          </mesh>
        </geometry>
        <surface>
          <contact>
            <ode/>
          </contact>
          <friction>
            <ode>
              <mu>1.1299999999999999</mu>
              <mu2>1.1299999999999999</mu2>
            </ode>
          </friction>
        </surface>
      </collision>
      <visual name='fingrip_finger3_base_link_visual'>
        <pose>0 0 0 0 0 0</pose>
        <geometry>
          <mesh>
            <scale>1 1 1</scale>
            <uri>meshes/visual/gripper/base_finger/base_finger.stl</uri>
          </mesh>
        </geometry>
        <material>
          <diffuse>0.25 0.25 0.25 1</diffuse>
          <ambient>0.25 0.25 0.25 1</ambient>
        </material>
      </visual>
    </link>
    <joint name='fingrip_finger3_proximal_joint' type='revolute'>
      <pose relative_to='fingrip_finger3_base_link'>0 -0.032550000000000003 0 0 0 0</pose>
      <parent>fingrip_finger3_base_link</parent>
      <child>fingrip_finger3_proximal_link</child>
      <axis>
        <xyz>0 0 1</xyz>
        <limit>
          <lower>-1.3</lower>
          <upper>0.31415999999999999</upper>
          <effort>20</effort>
          <velocity>0.20000000000000001</velocity>
        </limit>
        <dynamics>
          <damping>3</damping>
          <friction>0.40000000000000002</friction>
          <spring_reference>0</spring_reference>
          <spring_stiffness>0</spring_stiffness>
        </dynamics>
      </axis>
      <physics>
        <ode>
          <limit>
            <cfm>0</cfm>
            <erp>0.20000000000000001</erp>
          </limit>
        </ode>
      </physics>
    </joint>
    <link name='fingrip_finger3_proximal_link'>
      <pose relative_to='fingrip_finger3_proximal_joint'>0 0 0 0 0 0</pose>
      <inertial>
        <pose>0.034110000000000001 -0.010120000000000001 0 0 0 0</pose>
        <mass>0.2238453537819424</mass>
        <inertia>
          <ixx>9.2e-05</ixx>
          <ixy>-6.0999999999999999e-05</ixy>
          <ixz>0</ixz>
          <iyy>0.00031</iyy>
          <iyz>0</iyz>
          <izz>0.00031</izz>
        </inertia>
      </inertial>
      <collision name='fingrip_finger3_proximal_link_collision'>
        <pose>0 0 0 0 0 0</pose>
        <geometry>
          <mesh>
            <scale>1 1 1</scale>
            <uri>meshes/collision/gripper/proximal/short/proximal.stl</uri>
          </mesh>
        </geometry>
        <surface>
          <contact>
            <ode/>
          </contact>
          <friction>
            <ode>
              <mu>1.1299999999999999</mu>
              <mu2>1.1299999999999999</mu2>
            </ode>
          </friction>
        </surface>
      </collision>
      <visual name='fingrip_finger3_proximal_link_visual'>
        <pose>0 0 0 0 0 0</pose>
        <geometry>
          <mesh>
            <scale>1 1 1</scale>
            <uri>meshes/visual/gripper/proximal/short/proximal.stl</uri>
          </mesh>
        </geometry>
        <material>
          <diffuse>0.25 0.25 0.25 1</diffuse>
          <ambient>0.25 0.25 0.25 1</ambient>
        </material>
      </visual>
    </link>
    <plugin name='gz_ros2_control::GazeboSimROS2ControlPlugin' filename='libgz_ros2_control-system'>
      <parameters>/home/alex/additive_manufacturing/Planner4grasping/install/share/fingrip_moveit_config/config/controllers_effort.yaml</parameters>
    </plugin>
    <frame name='fingrip_hand_tcp_virtual_joint' attached_to='fingrip_hand'>
      <pose>0 0 0.12 0 0 0</pose>
    </frame>
    <frame name='fingrip_hand_tcp' attached_to='fingrip_hand_tcp_virtual_joint'>
      <pose>0 0 0 0 0 0</pose>
    </frame>
    <frame name='fingrip_joint_palm' attached_to='fingrip_hand'>
      <pose>0 0 0.012999999999999999 0 0 0</pose>
    </frame>
    <frame name='fingrip_palm' attached_to='fingrip_joint_palm'>
      <pose>0 0 0 0 0 0</pose>
    </frame>
    <frame name='fingrip_joint_wrist' attached_to='fingrip_link8'>
      <pose>0 0 0 0 0 0</pose>
    </frame>
    <frame name='fingrip_hand' attached_to='fingrip_joint_wrist'>
      <pose>0 0 0 0 0 0</pose>
    </frame>
    <frame name='fingrip_link8_virtual_joint' attached_to='fingrip_link7'>
      <pose>0 0 0.132936 0 0 0</pose>
    </frame>
    <frame name='fingrip_link8' attached_to='fingrip_link8_virtual_joint'>
      <pose>0 0 0 0 0 0</pose>
    </frame>
  </model>
</sdf>
