<sdf version='1.7'>
  <model name='fingrip'>
    <joint name='fingrip_joint_base' type='fixed'>
      <pose relative_to='__model__'>0 0 0 0 -0 0</pose>
      <parent>world</parent>
      <child>fingrip_link0</child>
    </joint>
    <link name='fingrip_link0'>
      <pose relative_to='fingrip_joint_base'>0 0 0 0 -0 0</pose>
      <inertial>
        <pose>-0.1 0 0.07 0 -0 0</pose>
        <mass>2.81427</mass>
        <inertia>
          <ixx>0.00753906</ixx>
          <ixy>-1.50531e-05</ixy>
          <ixz>-0.00121443</ixz>
          <iyy>0.010508</iyy>
          <iyz>1.04348e-05</iyz>
          <izz>0.00986493</izz>
        </inertia>
      </inertial>
      <collision name='fingrip_link0_collision'>
        <pose>0 0 0 0 -0 0</pose>
        <geometry>
          <mesh>
            <scale>1 1 1</scale>
            <uri>meshes/collision/arm/link0.stl</uri>
          </mesh>
        </geometry>
        <surface>
          <contact>
            <ode/>
          </contact>
          <friction>
            <ode>
              <mu>0.85</mu>
              <mu2>0.85</mu2>
            </ode>
          </friction>
        </surface>
      </collision>
      <visual name='fingrip_link0_visual'>
        <pose>0 0 0 0 -0 0</pose>
        <geometry>
          <mesh>
            <scale>1 1 1</scale>
            <uri>meshes/visual/arm/link0.stl</uri>
          </mesh>
        </geometry>
      </visual>
    </link>
    <joint name='fingrip_joint1' type='revolute'>
      <pose relative_to='fingrip_link0'>0 0 0.1575 0 -0 0</pose>
      <parent>fingrip_link0</parent>
      <child>fingrip_link1</child>
      <axis>
        <xyz>0 0 1</xyz>
        <limit>
          <lower>-2.96706</lower>
          <upper>2.96706</upper>
          <effort>87</effort>
          <velocity>1.48353</velocity>
        </limit>
        <dynamics>
          <damping>21.75</damping>
          <friction>3.48</friction>
          <spring_reference>0</spring_reference>
          <spring_stiffness>0</spring_stiffness>
        </dynamics>
      </axis>
      <physics>
        <ode>
          <limit>
            <cfm>0</cfm>
            <erp>0.2</erp>
          </limit>
        </ode>
      </physics>
    </joint>
    <link name='fingrip_link1'>
      <pose relative_to='fingrip_joint1'>0 0 0 0 -0 0</pose>
      <inertial>
        <pose>0 -0.03 0.12 0 -0 0</pose>
        <mass>2.64332</mass>
        <inertia>
          <ixx>0.0174051</ixx>
          <ixy>-8.68799e-09</ixy>
          <ixz>-1.62778e-08</ixz>
          <iyy>0.0153521</iyy>
          <iyz>0.00451086</iyz>
          <izz>0.00598789</izz>
        </inertia>
      </inertial>
      <collision name='fingrip_link1_collision'>
        <pose>0 0 0 0 -0 0</pose>
        <geometry>
          <mesh>
            <scale>1 1 1</scale>
            <uri>meshes/collision/arm/link1.stl</uri>
          </mesh>
        </geometry>
        <surface>
          <contact>
            <ode/>
          </contact>
          <friction>
            <ode>
              <mu>0.85</mu>
              <mu2>0.85</mu2>
            </ode>
          </friction>
        </surface>
      </collision>
      <visual name='fingrip_link1_visual'>
        <pose>0 0 0 0 -0 0</pose>
        <geometry>
          <mesh>
            <scale>1 1 1</scale>
            <uri>meshes/visual/arm/link1.stl</uri>
          </mesh>
        </geometry>
      </visual>
    </link>
    <joint name='fingrip_joint2' type='revolute'>
      <pose relative_to='fingrip_link1'>0 0 0.2025 1.5708 -0 -3.14159</pose>
      <parent>fingrip_link1</parent>
      <child>fingrip_link2</child>
      <axis>
        <xyz>0 0 1</xyz>
        <limit>
          <lower>-2.0944</lower>
          <upper>2.0944</upper>
          <effort>87</effort>
          <velocity>1.48353</velocity>
        </limit>
        <dynamics>
          <damping>21.75</damping>
          <friction>3.48</friction>
          <spring_reference>0</spring_reference>
          <spring_stiffness>0</spring_stiffness>
        </dynamics>
      </axis>
      <physics>
        <ode>
          <limit>
            <cfm>0</cfm>
            <erp>0.2</erp>
          </limit>
        </ode>
      </physics>
    </joint>
    <link name='fingrip_link2'>
      <pose relative_to='fingrip_joint2'>0 0 0 0 -0 0</pose>
      <inertial>
        <pose>0.00029 0.059 0.042 0 -0 0</pose>
        <mass>2.66528</mass>
        <inertia>
          <ixx>0.0177869</ixx>
          <ixy>8.70636e-08</ixy>
          <ixz>3.75207e-08</ixz>
          <iyy>0.00604413</iyy>
          <iyz>-0.00459949</iyz>
          <izz>0.015711</izz>
        </inertia>
      </inertial>
      <collision name='fingrip_link2_collision'>
        <pose>0 0 0 0 -0 0</pose>
        <geometry>
          <mesh>
            <scale>1 1 1</scale>
            <uri>meshes/collision/arm/link2.stl</uri>
          </mesh>
        </geometry>
        <surface>
          <contact>
            <ode/>
          </contact>
          <friction>
            <ode>
              <mu>0.85</mu>
              <mu2>0.85</mu2>
            </ode>
          </friction>
        </surface>
      </collision>
      <visual name='fingrip_link2_visual'>
        <pose>0 0 0 0 -0 0</pose>
        <geometry>
          <mesh>
            <scale>1 1 1</scale>
            <uri>meshes/visual/arm/link2.stl</uri>
          </mesh>
        </geometry>
      </visual>
    </link>
    <joint name='fingrip_joint3' type='revolute'>
      <pose relative_to='fingrip_link2'>0 0.2045 0 1.5708 -0 -3.14159</pose>
      <parent>fingrip_link2</parent>
      <child>fingrip_link3</child>
      <axis>
        <xyz>0 0 1</xyz>
        <limit>
          <lower>-2.96706</lower>
          <upper>2.96706</upper>
          <effort>87</effort>
          <velocity>1.74533</velocity>
        </limit>
        <dynamics>
          <damping>21.75</damping>
          <friction>3.48</friction>
          <spring_reference>0</spring_reference>
          <spring_stiffness>0</spring_stiffness>
        </dynamics>
      </axis>
      <physics>
        <ode>
          <limit>
            <cfm>0</cfm>
            <erp>0.2</erp>
          </limit>
        </ode>
      </physics>
    </joint>
    <link name='fingrip_link3'>
      <pose relative_to='fingrip_joint3'>0 0 0 0 -0 0</pose>
      <inertial>
        <pose>0 0.03 0.13 0 -0 0</pose>
        <mass>2.32937</mass>
        <inertia>
          <ixx>0.00754968</ixx>
          <ixy>-0.00243205</ixy>
          <ixz>-0.00325082</ixz>
          <iyy>0.00968068</iyy>
          <iyz>-0.00213163</iyz>
          <izz>0.00794456</izz>
        </inertia>
      </inertial>
      <collision name='fingrip_link3_collision'>
        <pose>0 0 0 0 -0 0</pose>
        <geometry>
          <mesh>
            <scale>1 1 1</scale>
            <uri>meshes/collision/arm/link3.stl</uri>
          </mesh>
        </geometry>
        <surface>
          <contact>
            <ode/>
          </contact>
          <friction>
            <ode>
              <mu>0.85</mu>
              <mu2>0.85</mu2>
            </ode>
          </friction>
        </surface>
      </collision>
      <visual name='fingrip_link3_visual'>
        <pose>0 0 0 0 -0 0</pose>
        <geometry>
          <mesh>
            <scale>1 1 1</scale>
            <uri>meshes/visual/arm/link3.stl</uri>
          </mesh>
        </geometry>
      </visual>
    </link>
    <joint name='fingrip_joint4' type='revolute'>
      <pose relative_to='fingrip_link3'>0 0 0.2155 1.5708 -0 0</pose>
      <parent>fingrip_link3</parent>
      <child>fingrip_link4</child>
      <axis>
        <xyz>0 0 1</xyz>
        <limit>
          <lower>-2.0944</lower>
          <upper>2.0944</upper>
          <effort>87</effort>
          <velocity>1.309</velocity>
        </limit>
        <dynamics>
          <damping>21.75</damping>
          <friction>3.48</friction>
          <spring_reference>0</spring_reference>
          <spring_stiffness>0</spring_stiffness>
        </dynamics>
      </axis>
      <physics>
        <ode>
          <limit>
            <cfm>0</cfm>
            <erp>0.2</erp>
          </limit>
        </ode>
      </physics>
    </joint>
    <link name='fingrip_link4'>
      <pose relative_to='fingrip_joint4'>0 0 0 0 -0 0</pose>
      <inertial>
        <pose>0 0.067 0.034 0 -0 0</pose>
        <mass>2.31048</mass>
        <inertia>
          <ixx>0.00776457</ixx>
          <ixy>0.00337148</ixy>
          <ixz>-0.00234362</ixz>
          <iyy>0.00801578</iyy>
          <iyz>0.00229175</iyz>
          <izz>0.00995588</izz>
        </inertia>
      </inertial>
      <collision name='fingrip_link4_collision'>
        <pose>0 0 0 0 -0 0</pose>
        <geometry>
          <mesh>
            <scale>1 1 1</scale>
            <uri>meshes/collision/arm/link4.stl</uri>
          </mesh>
        </geometry>
        <surface>
          <contact>
            <ode/>
          </contact>
          <friction>
            <ode>
              <mu>0.85</mu>
              <mu2>0.85</mu2>
            </ode>
          </friction>
        </surface>
      </collision>
      <visual name='fingrip_link4_visual'>
        <pose>0 0 0 0 -0 0</pose>
        <geometry>
          <mesh>
            <scale>1 1 1</scale>
            <uri>meshes/visual/arm/link4.stl</uri>
          </mesh>
        </geometry>
      </visual>
    </link>
    <joint name='fingrip_joint5' type='revolute'>
      <pose relative_to='fingrip_link4'>0 0.1845 0 1.5708 -0 3.14159</pose>
      <parent>fingrip_link4</parent>
      <child>fingrip_link5</child>
      <axis>
        <xyz>0 0 1</xyz>
        <limit>
          <lower>-2.96706</lower>
          <upper>2.96706</upper>
          <effort>12</effort>
          <velocity>2.26893</velocity>
        </limit>
        <dynamics>
          <damping>3</damping>
          <friction>0.48</friction>
          <spring_reference>0</spring_reference>
          <spring_stiffness>0</spring_stiffness>
        </dynamics>
      </axis>
      <physics>
        <ode>
          <limit>
            <cfm>0</cfm>
            <erp>0.2</erp>
          </limit>
        </ode>
      </physics>
    </joint>
    <link name='fingrip_link5'>
      <pose relative_to='fingrip_joint5'>0 0 0 0 -0 0</pose>
      <inertial>
        <pose>0.0001 0.021 0.076 0 -0 0</pose>
        <mass>2.62264</mass>
        <inertia>
          <ixx>0.0290705</ixx>
          <ixy>6.20874e-07</ixy>
          <ixz>-1.00592e-05</ixz>
          <iyy>0.0276385</iyy>
          <iyz>-0.00742431</iyz>
          <izz>0.00425111</izz>
        </inertia>
      </inertial>
      <collision name='fingrip_link5_collision'>
        <pose>0 0 0 0 -0 0</pose>
        <geometry>
          <mesh>
            <scale>1 1 1</scale>
            <uri>meshes/collision/arm/link5.stl</uri>
          </mesh>
        </geometry>
        <surface>
          <contact>
            <ode/>
          </contact>
          <friction>
            <ode>
              <mu>0.85</mu>
              <mu2>0.85</mu2>
            </ode>
          </friction>
        </surface>
      </collision>
      <visual name='fingrip_link5_visual'>
        <pose>0 0 0 0 -0 0</pose>
        <geometry>
          <mesh>
            <scale>1 1 1</scale>
            <uri>meshes/visual/arm/link5.stl</uri>
          </mesh>
        </geometry>
      </visual>
    </link>
    <joint name='fingrip_joint6' type='revolute'>
      <pose relative_to='fingrip_link5'>0 0 0.2155 1.5708 -0 0</pose>
      <parent>fingrip_link5</parent>
      <child>fingrip_link6</child>
      <axis>
        <xyz>0 0 1</xyz>
        <limit>
          <lower>-2.0944</lower>
          <upper>2.0944</upper>
          <effort>12</effort>
          <velocity>2.35619</velocity>
        </limit>
        <dynamics>
          <damping>3</damping>
          <friction>0.48</friction>
          <spring_reference>0</spring_reference>
          <spring_stiffness>0</spring_stiffness>
        </dynamics>
      </axis>
      <physics>
        <ode>
          <limit>
            <cfm>0</cfm>
            <erp>0.2</erp>
          </limit>
        </ode>
      </physics>
    </joint>
    <link name='fingrip_link6'>
      <pose relative_to='fingrip_joint6'>0 0 0 0 -0 0</pose>
      <inertial>
        <pose>0 0.00059 0.0004 0 -0 0</pose>
        <mass>1.50258</mass>
        <inertia>
          <ixx>0.00294056</ixx>
          <ixy>-0.000423911</ixy>
          <ixz>0.000610008</ixz>
          <iyy>0.00392105</iyy>
          <iyz>0.000126475</iyz>
          <izz>0.00541156</izz>
        </inertia>
      </inertial>
      <collision name='fingrip_link6_collision'>
        <pose>0 0 0 0 -0 0</pose>
        <geometry>
          <mesh>
            <scale>1 1 1</scale>
            <uri>meshes/collision/arm/link6.stl</uri>
          </mesh>
        </geometry>
        <surface>
          <contact>
            <ode/>
          </contact>
          <friction>
            <ode>
              <mu>0.85</mu>
              <mu2>0.85</mu2>
            </ode>
          </friction>
        </surface>
      </collision>
      <visual name='fingrip_link6_visual'>
        <pose>0 0 0 0 -0 0</pose>
        <geometry>
          <mesh>
            <scale>1 1 1</scale>
            <uri>meshes/visual/arm/link6.stl</uri>
          </mesh>
        </geometry>
      </visual>
    </link>
    <joint name='fingrip_joint7' type='revolute'>
      <pose relative_to='fingrip_link6'>0 0.081 0 1.5708 -0 -3.14159</pose>
      <parent>fingrip_link6</parent>
      <child>fingrip_link7</child>
      <axis>
        <xyz>0 0 1</xyz>
        <limit>
          <lower>-3.05433</lower>
          <upper>3.05433</upper>
          <effort>12</effort>
          <velocity>2.35619</velocity>
        </limit>
        <dynamics>
          <damping>3</damping>
          <friction>0.48</friction>
          <spring_reference>0</spring_reference>
          <spring_stiffness>0</spring_stiffness>
        </dynamics>
      </axis>
      <physics>
        <ode>
          <limit>
            <cfm>0</cfm>
            <erp>0.2</erp>
          </limit>
        </ode>
      </physics>
    </joint>
    <link name='fingrip_link7'>
      <pose relative_to='fingrip_joint7'>0 0 0 0 -0 0</pose>
      <inertial>
        <pose>0 0 0.053279 0 -0 0</pose>
        <mass>0.804982</mass>
        <inertia>
          <ixx>0.00386028</ixx>
          <ixy>-0.000118675</ixy>
          <ixz>3.86196e-05</ixz>
          <iyy>0.00294046</iyy>
          <iyz>-9.04848e-05</iyz>
          <izz>0.00168375</izz>
        </inertia>
      </inertial>
      <collision name='fingrip_link7_collision'>
        <pose>0 0 0 0 -0 0</pose>
        <geometry>
          <mesh>
            <scale>1 1 1</scale>
            <uri>meshes/collision/arm/link7.stl</uri>
          </mesh>
        </geometry>
        <surface>
          <contact>
            <ode/>
          </contact>
          <friction>
            <ode>
              <mu>0.85</mu>
              <mu2>0.85</mu2>
            </ode>
          </friction>
        </surface>
      </collision>
      <collision name='fingrip_link7_fixed_joint_lump__fingrip_hand_collision_1'>
        <pose>0 0 0.132936 0 -0 0</pose>
        <geometry>
          <mesh>
            <scale>1 1 1</scale>
            <uri>meshes/collision/gripper/paume/base_hand_paume1.stl</uri>
          </mesh>
        </geometry>
        <surface>
          <contact>
            <ode/>
          </contact>
          <friction>
            <ode>
              <mu>0.85</mu>
              <mu2>0.85</mu2>
            </ode>
          </friction>
        </surface>
      </collision>
      <collision name='fingrip_link7_fixed_joint_lump__fingrip_palm_collision_2'>
        <pose>0 0 0.145936 0 -0 0</pose>
        <geometry>
          <mesh>
            <scale>1 1 1</scale>
            <uri>meshes/collision/gripper/case/case_3d.stl</uri>
          </mesh>
        </geometry>
        <surface>
          <contact>
            <ode/>
          </contact>
          <friction>
            <ode>
              <mu>0.85</mu>
              <mu2>0.85</mu2>
            </ode>
          </friction>
        </surface>
      </collision>
      <visual name='fingrip_link7_visual'>
        <pose>0 0 0 0 -0 0</pose>
        <geometry>
          <mesh>
            <scale>1 1 1</scale>
            <uri>meshes/visual/arm/link7.stl</uri>
          </mesh>
        </geometry>
      </visual>
      <visual name='fingrip_link7_fixed_joint_lump__fingrip_hand_visual_1'>
        <pose>0 0 0.132936 0 -0 0</pose>
        <geometry>
          <mesh>
            <scale>1 1 1</scale>
            <uri>meshes/visual/gripper/paume/base_hand_paume1.stl</uri>
          </mesh>
        </geometry>
      </visual>
      <visual name='fingrip_link7_fixed_joint_lump__fingrip_palm_visual_2'>
        <pose>0 0 0.145936 0 -0 0</pose>
        <geometry>
          <mesh>
            <scale>1 1 1</scale>
            <uri>meshes/visual/gripper/case/case_3d.stl</uri>
          </mesh>
        </geometry>
      </visual>
    </link>
    <joint name='fingrip_finger1_base_joint' type='revolute'>
      <pose relative_to='fingrip_link7'>0.054 0.054 0.231787 -3.14159 -1.5708 0</pose>
      <parent>fingrip_link7</parent>
      <child>fingrip_finger1_base_link</child>
      <axis>
        <xyz>1 0 0</xyz>
        <limit>
          <lower>-1.5708</lower>
          <upper>0</upper>
          <effort>20</effort>
          <velocity>0.2</velocity>
        </limit>
        <dynamics>
          <damping>3</damping>
          <friction>0.4</friction>
          <spring_reference>0</spring_reference>
          <spring_stiffness>0</spring_stiffness>
        </dynamics>
      </axis>
      <physics>
        <ode>
          <limit>
            <cfm>0</cfm>
            <erp>0.2</erp>
          </limit>
        </ode>
      </physics>
    </joint>
    <link name='fingrip_finger1_base_link'>
      <pose relative_to='fingrip_finger1_base_joint'>0 0 0 0 -0 0</pose>
      <inertial>
        <pose>-0.0465 -0.04775 0 0 -0 0</pose>
        <mass>0.223845</mass>
        <inertia>
          <ixx>0.0007</ixx>
          <ixy>-0.0002</ixy>
          <ixz>0</ixz>
          <iyy>0.0006</iyy>
          <iyz>0</iyz>
          <izz>0.0011</izz>
        </inertia>
      </inertial>
      <collision name='fingrip_finger1_base_link_collision'>
        <pose>0 0 0 0 -0 0</pose>
        <geometry>
          <mesh>
            <scale>1 1 1</scale>
            <uri>meshes/collision/gripper/base_finger/base_finger.stl</uri>
          </mesh>
        </geometry>
        <surface>
          <contact>
            <ode/>
          </contact>
          <friction>
            <ode>
              <mu>1.13</mu>
              <mu2>1.13</mu2>
            </ode>
          </friction>
        </surface>
      </collision>
      <visual name='fingrip_finger1_base_link_visual'>
        <pose>0 0 0 0 -0 0</pose>
        <geometry>
          <mesh>
            <scale>1 1 1</scale>
            <uri>meshes/visual/gripper/base_finger/base_finger.stl</uri>
          </mesh>
        </geometry>
      </visual>
    </link>
    <joint name='fingrip_finger1_proximal_joint' type='revolute'>
      <pose relative_to='fingrip_finger1_base_link'>0 -0.03255 0 0 -0 0</pose>
      <parent>fingrip_finger1_base_link</parent>
      <child>fingrip_finger1_proximal_link</child>
      <axis>
        <xyz>0 0 1</xyz>
        <limit>
          <lower>-1.3</lower>
          <upper>0.31416</upper>
          <effort>20</effort>
          <velocity>0.2</velocity>
        </limit>
        <dynamics>
          <damping>3</damping>
          <friction>0.4</friction>
          <spring_reference>0</spring_reference>
          <spring_stiffness>0</spring_stiffness>
        </dynamics>
      </axis>
      <physics>
        <ode>
          <limit>
            <cfm>0</cfm>
            <erp>0.2</erp>
          </limit>
        </ode>
      </physics>
    </joint>
    <link name='fingrip_finger1_proximal_link'>
      <pose relative_to='fingrip_finger1_proximal_joint'>0 0 0 0 -0 0</pose>
      <inertial>
        <pose>0.03411 -0.01012 0 0 -0 0</pose>
        <mass>0.223845</mass>
        <inertia>
          <ixx>9.2e-05</ixx>
          <ixy>-6.1e-05</ixy>
          <ixz>0</ixz>
          <iyy>0.00031</iyy>
          <iyz>0</iyz>
          <izz>0.00031</izz>
        </inertia>
      </inertial>
      <collision name='fingrip_finger1_proximal_link_collision'>
        <pose>0 0 0 0 -0 0</pose>
        <geometry>
          <mesh>
            <scale>1 1 1</scale>
            <uri>meshes/collision/gripper/proximal/short/proximal.stl</uri>
          </mesh>
        </geometry>
        <surface>
          <contact>
            <ode/>
          </contact>
          <friction>
            <ode>
              <mu>1.13</mu>
              <mu2>1.13</mu2>
            </ode>
          </friction>
        </surface>
      </collision>
      <visual name='fingrip_finger1_proximal_link_visual'>
        <pose>0 0 0 0 -0 0</pose>
        <geometry>
          <mesh>
            <scale>1 1 1</scale>
            <uri>meshes/visual/gripper/proximal/short/proximal.stl</uri>
          </mesh>
        </geometry>
      </visual>
    </link>
    <joint name='fingrip_finger2_base_joint' type='revolute'>
      <pose relative_to='fingrip_link7'>0.054 -0.054 0.231787 -0 -1.5708 0</pose>
      <parent>fingrip_link7</parent>
      <child>fingrip_finger2_base_link</child>
      <axis>
        <xyz>1 0 0</xyz>
        <limit>
          <lower>0</lower>
          <upper>1.5708</upper>
          <effort>20</effort>
          <velocity>0.2</velocity>
        </limit>
        <dynamics>
          <damping>3</damping>
          <friction>0.4</friction>
          <spring_reference>0</spring_reference>
          <spring_stiffness>0</spring_stiffness>
        </dynamics>
      </axis>
      <physics>
        <ode>
          <limit>
            <cfm>0</cfm>
            <erp>0.2</erp>
          </limit>
        </ode>
      </physics>
    </joint>
    <link name='fingrip_finger2_base_link'>
      <pose relative_to='fingrip_finger2_base_joint'>0 0 0 0 -0 0</pose>
      <inertial>
        <pose>-0.0465 -0.04775 0 0 -0 0</pose>
        <mass>0.223845</mass>
        <inertia>
          <ixx>0.0007</ixx>
          <ixy>-0.0002</ixy>
          <ixz>0</ixz>
          <iyy>0.0006</iyy>
          <iyz>0</iyz>
          <izz>0.0011</izz>
        </inertia>
      </inertial>
      <collision name='fingrip_finger2_base_link_collision'>
        <pose>0 0 0 0 -0 0</pose>
        <geometry>
          <mesh>
            <scale>1 1 1</scale>
            <uri>meshes/collision/gripper/base_finger/base_finger.stl</uri>
          </mesh>
        </geometry>
        <surface>
          <contact>
            <ode/>
          </contact>
          <friction>
            <ode>
              <mu>1.13</mu>
              <mu2>1.13</mu2>
            </ode>
          </friction>
        </surface>
      </collision>
      <visual name='fingrip_finger2_base_link_visual'>
        <pose>0 0 0 0 -0 0</pose>
        <geometry>
          <mesh>
            <scale>1 1 1</scale>
            <uri>meshes/visual/gripper/base_finger/base_finger.stl</uri>
          </mesh>
        </geometry>
      </visual>
    </link>
    <joint name='fingrip_finger2_proximal_joint' type='revolute'>
      <pose relative_to='fingrip_finger2_base_link'>0 -0.03255 0 0 -0 0</pose>
      <parent>fingrip_finger2_base_link</parent>
      <child>fingrip_finger2_proximal_link</child>
      <axis>
        <xyz>0 0 1</xyz>
        <limit>
          <lower>-1.3</lower>
          <upper>0.31416</upper>
          <effort>20</effort>
          <velocity>0.2</velocity>
        </limit>
        <dynamics>
          <damping>3</damping>
          <friction>0.4</friction>
          <spring_reference>0</spring_reference>
          <spring_stiffness>0</spring_stiffness>
        </dynamics>
      </axis>
      <physics>
        <ode>
          <limit>
            <cfm>0</cfm>
            <erp>0.2</erp>
          </limit>
        </ode>
      </physics>
    </joint>
    <link name='fingrip_finger2_proximal_link'>
      <pose relative_to='fingrip_finger2_proximal_joint'>0 0 0 0 -0 0</pose>
      <inertial>
        <pose>0.03411 -0.01012 0 0 -0 0</pose>
        <mass>0.223845</mass>
        <inertia>
          <ixx>9.2e-05</ixx>
          <ixy>-6.1e-05</ixy>
          <ixz>0</ixz>
          <iyy>0.00031</iyy>
          <iyz>0</iyz>
          <izz>0.00031</izz>
        </inertia>
      </inertial>
      <collision name='fingrip_finger2_proximal_link_collision'>
        <pose>0 0 0 0 -0 0</pose>
        <geometry>
          <mesh>
            <scale>1 1 1</scale>
            <uri>meshes/collision/gripper/proximal/short/proximal.stl</uri>
          </mesh>
        </geometry>
        <surface>
          <contact>
            <ode/>
          </contact>
          <friction>
            <ode>
              <mu>1.13</mu>
              <mu2>1.13</mu2>
            </ode>
          </friction>
        </surface>
      </collision>
      <visual name='fingrip_finger2_proximal_link_visual'>
        <pose>0 0 0 0 -0 0</pose>
        <geometry>
          <mesh>
            <scale>1 1 1</scale>
            <uri>meshes/visual/gripper/proximal/short/proximal.stl</uri>
          </mesh>
        </geometry>
      </visual>
    </link>
    <joint name='fingrip_finger3_base_joint' type='fixed'>
      <pose relative_to='fingrip_link7'>-0.04398 0 0.231787 -1.5708 -1.5708 0</pose>
      <parent>fingrip_link7</parent>
      <child>fingrip_finger3_base_link</child>
      <axis>
        <dynamics>
          <spring_reference>0</spring_reference>
          <spring_stiffness>0</spring_stiffness>
        </dynamics>
        <xyz>0 0 1</xyz>
        <limit>
          <lower>-1e+16</lower>
          <upper>1e+16</upper>
        </limit>
      </axis>
      <physics>
        <ode>
          <limit>
            <cfm>0</cfm>
            <erp>0.2</erp>
          </limit>
        </ode>
      </physics>
    </joint>
    <link name='fingrip_finger3_base_link'>
      <pose relative_to='fingrip_finger3_base_joint'>0 0 0 0 -0 0</pose>
      <inertial>
        <pose>-0.0465 -0.04775 0 0 -0 0</pose>
        <mass>0.223845</mass>
        <inertia>
          <ixx>0.0007</ixx>
          <ixy>-0.0002</ixy>
          <ixz>0</ixz>
          <iyy>0.0006</iyy>
          <iyz>0</iyz>
          <izz>0.0011</izz>
        </inertia>
      </inertial>
      <collision name='fingrip_finger3_base_link_collision'>
        <pose>0 0 0 0 -0 0</pose>
        <geometry>
          <mesh>
            <scale>1 1 1</scale>
            <uri>meshes/collision/gripper/base_finger/base_finger.stl</uri>
          </mesh>
        </geometry>
        <surface>
          <contact>
            <ode/>
          </contact>
          <friction>
            <ode>
              <mu>1.13</mu>
              <mu2>1.13</mu2>
            </ode>
          </friction>
        </surface>
      </collision>
      <visual name='fingrip_finger3_base_link_visual'>
        <pose>0 0 0 0 -0 0</pose>
        <geometry>
          <mesh>
            <scale>1 1 1</scale>
            <uri>meshes/visual/gripper/base_finger/base_finger.stl</uri>
          </mesh>
        </geometry>
      </visual>
    </link>
    <joint name='fingrip_finger3_proximal_joint' type='revolute'>
      <pose relative_to='fingrip_finger3_base_link'>0 -0.03255 0 0 -0 0</pose>
      <parent>fingrip_finger3_base_link</parent>
      <child>fingrip_finger3_proximal_link</child>
      <axis>
        <xyz>0 0 1</xyz>
        <limit>
          <lower>-1.3</lower>
          <upper>0.31416</upper>
          <effort>20</effort>
          <velocity>0.2</velocity>
        </limit>
        <dynamics>
          <damping>3</damping>
          <friction>0.4</friction>
          <spring_reference>0</spring_reference>
          <spring_stiffness>0</spring_stiffness>
        </dynamics>
      </axis>
      <physics>
        <ode>
          <limit>
            <cfm>0</cfm>
            <erp>0.2</erp>
          </limit>
        </ode>
      </physics>
    </joint>
    <link name='fingrip_finger3_proximal_link'>
      <pose relative_to='fingrip_finger3_proximal_joint'>0 0 0 0 -0 0</pose>
      <inertial>
        <pose>0.03411 -0.01012 0 0 -0 0</pose>
        <mass>0.223845</mass>
        <inertia>
          <ixx>9.2e-05</ixx>
          <ixy>-6.1e-05</ixy>
          <ixz>0</ixz>
          <iyy>0.00031</iyy>
          <iyz>0</iyz>
          <izz>0.00031</izz>
        </inertia>
      </inertial>
      <collision name='fingrip_finger3_proximal_link_collision'>
        <pose>0 0 0 0 -0 0</pose>
        <geometry>
          <mesh>
            <scale>1 1 1</scale>
            <uri>meshes/collision/gripper/proximal/short/proximal.stl</uri>
          </mesh>
        </geometry>
        <surface>
          <contact>
            <ode/>
          </contact>
          <friction>
            <ode>
              <mu>1.13</mu>
              <mu2>1.13</mu2>
            </ode>
          </friction>
        </surface>
      </collision>
      <visual name='fingrip_finger3_proximal_link_visual'>
        <pose>0 0 0 0 -0 0</pose>
        <geometry>
          <mesh>
            <scale>1 1 1</scale>
            <uri>meshes/visual/gripper/proximal/short/proximal.stl</uri>
          </mesh>
        </geometry>
      </visual>
    </link>
  </model>
</sdf>
